<sdf version='1.6'>
  <world name='default'>
    <light name='sun' type='directional'>
      <cast_shadows>1</cast_shadows>
      <pose frame=''>0 0 10 0 -0 0</pose>
      <diffuse>0.8 0.8 0.8 1</diffuse>
      <specular>0.2 0.2 0.2 1</specular>
      <attenuation>
        <range>1000</range>
        <constant>0.9</constant>
        <linear>0.01</linear>
        <quadratic>0.001</quadratic>
      </attenuation>
      <direction>-0.5 0.1 -0.9</direction>
    </light>
    <model name='ground_plane'>
      <static>1</static>
      <link name='link'>
        <collision name='collision'>
          <geometry>
            <plane>
              <normal>0 0 1</normal>
              <size>100 100</size>
            </plane>
          </geometry>
          <surface>
            <contact>
              <collide_bitmask>65535</collide_bitmask>
              <ode/>
            </contact>
            <friction>
              <ode>
                <mu>100</mu>
                <mu2>50</mu2>
              </ode>
              <torsional>
                <ode/>
              </torsional>
            </friction>
            <bounce/>
          </surface>
          <max_contacts>10</max_contacts>
        </collision>
        <visual name='visual'>
          <cast_shadows>0</cast_shadows>
          <geometry>
            <plane>
              <normal>0 0 1</normal>
              <size>100 100</size>
            </plane>
          </geometry>
          <material>
            <script>
              <uri>file://media/materials/scripts/gazebo.material</uri>
              <name>Gazebo/Grey</name>
            </script>
          </material>
        </visual>
        <self_collide>0</self_collide>
        <enable_wind>0</enable_wind>
        <kinematic>0</kinematic>
      </link>
    </model>
    <state world_name='default'>
      <sim_time>2162 915000000</sim_time>
      <real_time>41 848287217</real_time>
      <wall_time>1629784284 513544858</wall_time>
      <iterations>9077</iterations>
      <model name='bookshelf'>
        <pose frame=''>3.52244 0.001709 0 0 0 -1.57</pose>
        <scale>1 1 1</scale>
        <link name='link'>
          <pose frame=''>3.52244 0.001709 0 0 0 -1.57</pose>
          <velocity>0 0 0 0 -0 0</velocity>
          <acceleration>0 0 0 0 -0 0</acceleration>
          <wrench>0 0 0 0 -0 0</wrench>
        </link>
      </model>
      <model name='grey_wall'>
        <pose frame=''>2.17689 -1.15773 0 0 -0 0</pose>
        <scale>1 1 1</scale>
        <link name='link'>
          <pose frame=''>2.17689 -1.15773 1.4 0 -0 0</pose>
          <velocity>0 0 0 0 -0 0</velocity>
          <acceleration>0 0 0 0 -0 0</acceleration>
          <wrench>0 0 0 0 -0 0</wrench>
        </link>
      </model>
      <model name='grey_wall_0'>
        <pose frame=''>2.24542 1.86727 0 0 -0 0</pose>
        <scale>1 1 1</scale>
        <link name='link'>
          <pose frame=''>2.24542 1.86727 1.4 0 -0 0</pose>
          <velocity>0 0 0 0 -0 0</velocity>
          <acceleration>0 0 0 0 -0 0</acceleration>
          <wrench>0 0 0 0 -0 0</wrench>
        </link>
      </model>
      <model name='grey_wall_1'>
        <pose frame=''>3.69979 0.668691 0 0 -0 1.57</pose>
        <scale>1 1 1</scale>
        <link name='link'>
          <pose frame=''>3.69979 0.668691 1.4 0 -0 1.57</pose>
          <velocity>0 0 0 0 -0 0</velocity>
          <acceleration>0 0 0 0 -0 0</acceleration>
          <wrench>0 0 0 0 -0 0</wrench>
        </link>
      </model>
      <model name='grey_wall_1_clone'>
        <pose frame=''>-1.49276 0.228869 0 0 -0 1.57</pose>
        <scale>1 1 1</scale>
        <link name='link'>
          <pose frame=''>-1.49276 0.228869 1.4 0 -0 1.57</pose>
          <velocity>0 0 0 0 -0 0</velocity>
          <acceleration>0 0 0 0 -0 0</acceleration>
          <wrench>0 0 0 0 -0 0</wrench>
        </link>
      </model>
      <model name='ground_plane'>
        <pose frame=''>0 0 0 0 -0 0</pose>
        <scale>1 1 1</scale>
        <link name='link'>
          <pose frame=''>0 0 0 0 -0 0</pose>
          <velocity>0 0 0 0 -0 0</velocity>
          <acceleration>0 0 0 0 -0 0</acceleration>
          <wrench>0 0 0 0 -0 0</wrench>
        </link>
      </model>
      <model name='marker005_clone'>
        <pose frame=''>3.10415 0.46344 0.812883 0 1.57 0</pose>
        <scale>1 1 1</scale>
        <link name='link'>
          <pose frame=''>3.10415 0.46344 0.812883 0 1.57 0</pose>
          <velocity>0 0 0 0 -0 0</velocity>
          <acceleration>0 0 0 0 -0 0</acceleration>
          <wrench>0 0 0 0 -0 0</wrench>
        </link>
      </model>
      <model name='marker006_clone'>
        <pose frame=''>3.0794 -0.448352 0.839134 0 1.57 0</pose>
        <scale>1 1 1</scale>
        <link name='link'>
          <pose frame=''>3.0794 -0.448352 0.839134 0 1.57 0</pose>
          <velocity>0 0 0 0 -0 0</velocity>
          <acceleration>0 0 0 0 -0 0</acceleration>
          <wrench>0 0 0 0 -0 0</wrench>
        </link>
      </model>
      <model name='seed_r7'>
        <pose frame=''>0.037794 0.016731 0.000998 -1.1e-05 1e-06 0.000311</pose>
        <scale>1 1 1</scale>
        <link name='base_link'>
          <pose frame=''>0.037794 0.016731 0.000998 -1.1e-05 1e-06 0.000311</pose>
          <velocity>0.000225 -0.001148 -0.001927 -0.010792 0.000631 -0.00131</velocity>
          <acceleration>1.30058 0.174238 -4.36706 -1.38307 0.693038 1.83192</acceleration>
          <wrench>107.747 14.4349 -361.793 0 -0 0</wrench>
        </link>
        <link name='body_link'>
          <pose frame=''>0.037729 0.016734 1.06645 -2.5e-05 -0.000172 0.000333</pose>
          <velocity>0.002537 0.001198 -6e-05 0.002885 0.005762 -0.001866</velocity>
          <acceleration>0.599707 3.29761 0.647851 -3.04231 -0.977557 -1.3746</acceleration>
          <wrench>6.32751 34.7931 6.83548 0 -0 0</wrench>
        </link>
        <link name='head_base_link'>
          <pose frame=''>0.037649 0.016742 1.52445 1.9e-05 -0.00018 0.000336</pose>
          <velocity>0.004231 -0.000158 -4e-06 0.004831 -0.006777 -0.000668</velocity>
          <acceleration>-1.28476 3.28928 1.20453 1.3875 -1.56249 1.73606</acceleration>
          <wrench>-0.128476 0.328928 0.120453 0 -0 0</wrench>
        </link>
        <link name='head_link'>
          <pose frame=''>0.037649 0.016742 1.52445 2e-05 -0.000178 0.000336</pose>
          <velocity>0.004303 -0.000173 -7e-06 0.002692 -0.003933 -0.001044</velocity>
          <acceleration>-2.31041 3.62473 1.21946 -2.52019 0.4365 0.834231</acceleration>
          <wrench>-2.25034 3.53048 1.18775 0 -0 0</wrench>
        </link>
        <link name='hip_center'>
          <pose frame=''>0.037729 0.016735 1.06643 -9e-06 -0.00017 0.000336</pose>
          <velocity>0.002585 0.000399 0.000598 0.00247 0.005149 0.000664</velocity>
          <acceleration>1.13573 3.78888 2.34334 -0.378734 0.505499 1.69541</acceleration>
          <wrench>0.113573 0.378888 0.234334 0 -0 0</wrench>
        </link>
        <link name='hip_sphere_link'>
          <pose frame=''>0.037762 0.016733 0.930986 -1e-06 -0.000228 0.000329</pose>
          <velocity>0.001706 0.003718 -0.001579 0.003005 0.004851 -0.006794</velocity>
          <acceleration>0.761025 7.29094 -3.15392 1.06834 0.550334 1.99797</acceleration>
          <wrench>0.956609 9.16471 -3.96448 0 -0 0</wrench>
        </link>
        <link name='l_elbow_link'>
          <pose frame=''>0.054633 0.200687 1.10991 -0.000176 -0.000687 0.000373</pose>
          <velocity>0.003324 -0.003392 0.000273 -0.013712 0.006466 -0.006295</velocity>
          <acceleration>1.09448 5.54165 2.50437 2.84299 0.464803 -1.35768</acceleration>
          <wrench>0.778171 3.94012 1.78061 0 -0 0</wrench>
        </link>
        <link name='l_forearm_link'>
          <pose frame=''>0.019682 0.200661 1.03988 -0.000186 -0.000692 0.000308</pose>
          <velocity>0.00286 -0.004174 0.000447 -0.015459 0.00802 -0.007182</velocity>
          <acceleration>1.34005 5.26418 2.65653 1.87442 -0.614028 -0.309045</acceleration>
          <wrench>0.176886 0.694871 0.350662 0 -0 0</wrench>
        </link>
        <link name='l_hand_link'>
          <pose frame=''>0.019817 0.200624 0.844376 -0.000358 -0.000972 0.000308</pose>
          <velocity>0.001341 -0.007139 0.000343 -0.019549 0.01131 -0.016412</velocity>
          <acceleration>1.08574 3.95803 2.95664 0.98587 1.41237 -3.07358</acceleration>
          <wrench>0.198691 0.72432 0.541065 0 -0 0</wrench>
        </link>
        <link name='l_indexbase_link'>
          <pose frame=''>0.019924 0.213583 0.729372 0.003357 -0.000972 0.000308</pose>
          <velocity>0.000152 -0.009379 0.000102 -0.005945 0.011239 -0.014875</velocity>
          <acceleration>-0.019574 4.93409 1.22316 -0.912967 1.5293 1.37569</acceleration>
          <wrench>-0.005872 1.48023 0.366948 0 -0 0</wrench>
        </link>
        <link name='l_shoulder_center'>
          <pose frame=''>0.019438 0.210713 1.39939 -0.000179 -0.00066 0.000416</pose>
          <velocity>0.004775 0.000613 0.00036 -0.011817 0.004689 -0.007567</velocity>
          <acceleration>-0.732625 3.35306 2.31321 0.124754 -1.33052 2.88734</acceleration>
          <wrench>-0.545073 2.49467 1.72103 0 -0 0</wrench>
        </link>
        <link name='l_shoulder_link'>
          <pose frame=''>0.019482 0.150933 1.37134 -0.00016 -0.000657 0.000419</pose>
          <velocity>0.004503 0.00056 0.000237 0.007846 0.005698 -0.002993</velocity>
          <acceleration>-0.846851 2.79191 2.16062 3.12454 1.27253 -0.608884</acceleration>
          <wrench>-0.204938 0.675641 0.52287 0 -0 0</wrench>
        </link>
        <link name='l_thumb_link'>
          <pose frame=''>0.019901 0.178241 0.76474 -0.000311 -0.000971 0.000309</pose>
          <velocity>8.2e-05 -0.008695 0.000809 -0.018658 0.009927 -0.010833</velocity>
          <acceleration>-0.094001 3.24955 3.9036 -1.71386 -0.612719 3.01846</acceleration>
          <wrench>-0.0094 0.324955 0.39036 0 -0 0</wrench>
        </link>
        <link name='l_upperarm_link'>
          <pose frame=''>0.019526 0.2007 1.27239 -0.000173 -0.000662 0.000375</pose>
          <velocity>0.004078 -0.001164 0.000461 -0.01273 0.004889 -0.006349</velocity>
          <acceleration>0.045227 4.54838 2.41732 -1.2249 -0.388537 -1.33012</acceleration>
          <wrench>0.02596 2.61077 1.38754 0 -0 0</wrench>
        </link>
        <link name='l_wrist_center'>
          <pose frame=''>0.019817 0.200624 0.844376 -0.00021 -0.000975 0.000308</pose>
          <velocity>0.00143 -0.007062 0.000322 -0.024259 0.013478 -0.012859</velocity>
          <acceleration>1.9458 5.39321 3.03279 -0.703939 -0.630419 -0.321719</acceleration>
          <wrench>0.09729 0.26966 0.151639 0 -0 0</wrench>
        </link>
        <link name='leg_base_link'>
          <pose frame=''>0.037777 0.016733 0.86599 3e-06 -0.00023 0.0003</pose>
          <velocity>0.001335 0.004042 -0.001751 0.000846 0.005412 -0.010545</velocity>
          <acceleration>-0.161468 7.59021 -3.78388 1.63425 -1.3621 -2.28333</acceleration>
          <wrench>-1.59903 75.1662 -37.4719 0 -0 0</wrench>
        </link>
        <link name='leg_knee_link'>
          <pose frame=''>0.037792 0.016735 0.495992 -2e-06 -8.7e-05 0.000312</pose>
          <velocity>0.000329 0.00328 -0.001827 -0.005145 -0.001118 -0.000886</velocity>
          <acceleration>4.61066 4.88184 -4.00264 -1.83454 -0.576481 -1.47453</acceleration>
          <wrench>9.52926 10.0897 -8.27261 0 -0 0</wrench>
        </link>
        <link name='leg_shank_link'>
          <pose frame=''>0.037794 0.016733 0.245995 -5e-06 -9e-06 0.000312</pose>
          <velocity>0.000379 0.001177 -0.001878 -0.007079 -0.000161 -0.00076</velocity>
          <acceleration>3.70488 3.01513 -4.50768 -0.6268 0.282626 1.79273</acceleration>
          <wrench>7.65722 6.23164 -9.31643 0 -0 0</wrench>
        </link>
        <link name='leg_shank_link_dummy'>
          <pose frame=''>0.069614 0.016744 0.277818 -1.1e-05 -0.000172 0.000311</pose>
          <velocity>0.0004 0.001915 -0.001955 -0.010605 -0.017739 -0.001274</velocity>
          <acceleration>-0.757286 3.46018 -5.634 1.94239 0.7831 -1.27378</acceleration>
          <wrench>-0.302914 1.38407 -2.2536 0 -0 0</wrench>
        </link>
        <link name='leg_thigh_link'>
          <pose frame=''>0.037782 0.016734 0.61599 2e-06 -7e-06 0.000302</pose>
          <velocity>0.000205 0.003533 -0.001749 0.001189 0.004174 -0.009931</velocity>
          <acceleration>1.68301 6.28045 -4.26989 1.97073 -0.048626 -1.66728</acceleration>
          <wrench>4.4149 16.4749 -11.2008 0 -0 0</wrench>
        </link>
        <link name='leg_thigh_link_dummy'>
          <pose frame=''>0.069605 0.016745 0.58418 -8e-06 -5e-05 0.000312</pose>
          <velocity>0.000243 0.004158 -0.001877 -0.008939 -0.037312 -0.000829</velocity>
          <acceleration>-0.564547 7.29998 -5.52701 0.655659 0.811412 -1.4182</acceleration>
          <wrench>-0.225819 2.91999 -2.2108 0 -0 0</wrench>
        </link>
        <link name='neck_link'>
          <pose frame=''>0.037668 0.016742 1.41995 -4e-06 -0.000178 0.000336</pose>
          <velocity>0.004283 0.000183 -4.4e-05 0.003757 0.000277 -0.00168</velocity>
          <acceleration>-0.724736 2.99736 0.77444 3.08045 0.905625 -0.741884</acceleration>
          <wrench>-0.247135 1.0221 0.264084 0 -0 0</wrench>
        </link>
        <link name='r_elbow_link'>
          <pose frame=''>0.054675 -0.16714 1.10992 0.000404 -0.000302 0.000296</pose>
          <velocity>-0.0054 0.003897 -0.000874 0.051004 0.041092 -0.008126</velocity>
          <acceleration>-3.02478 -51.9269 -3.9118 -1.99051 0.581926 -1.65441</acceleration>
          <wrench>-2.15062 -36.92 -2.78129 0 -0 0</wrench>
        </link>
        <link name='r_forearm_link'>
          <pose frame=''>0.019695 -0.167119 1.03991 0.000415 -0.000254 0.000297</pose>
          <velocity>-0.008455 0.008607 0.00099 0.090438 0.045802 -0.007796</velocity>
          <acceleration>-5.52629 -47.6907 -4.0549 -3.03399 0.790074 -1.47072</acceleration>
          <wrench>-0.729471 -6.29517 -0.535247 0 -0 0</wrench>
        </link>
        <link name='r_hand_link'>
          <pose frame=''>0.019746 -0.167036 0.844406 0.000218 -5.6e-05 0.000376</pose>
          <velocity>-0.017203 0.024348 0.001831 0.248989 0.098456 -0.004695</velocity>
          <acceleration>-12.4212 -5.47607 -3.92613 0.921541 0.907297 -1.28837</acceleration>
          <wrench>-2.27308 -1.00212 -0.718481 0 -0 0</wrench>
        </link>
        <link name='r_indexbase_link'>
          <pose frame=''>0.019756 -0.180011 0.729403 -0.003709 -5.9e-05 0.000362</pose>
          <velocity>-0.028603 0.052805 -0.001413 -0.224544 0.097984 -0.005323</velocity>
          <acceleration>-14.9051 6.7505 -11.283 0.365358 0.45467 -1.89322</acceleration>
          <wrench>-4.47153 2.02515 -3.38491 0 -0 0</wrench>
        </link>
        <link name='r_shoulder_center'>
          <pose frame=''>0.019573 -0.177229 1.3994 0.000434 -0.000317 0.000327</pose>
          <velocity>0.005308 -0.002762 -1.6e-05 0.018889 0.039736 -0.006149</velocity>
          <acceleration>1.0952 -16.632 -3.87909 2.31222 1.53425 2.00019</acceleration>
          <wrench>0.814829 -12.3742 -2.88604 0 -0 0</wrench>
        </link>
        <link name='r_shoulder_link'>
          <pose frame=''>0.019571 -0.117456 1.37135 0.000404 -0.000418 0.000282</pose>
          <velocity>0.004179 -0.001425 0.000197 -0.041674 0.033639 0.001038</velocity>
          <acceleration>1.75746 -0.817903 1.38443 -1.71989 0.905253 -0.363171</acceleration>
          <wrench>0.425306 -0.197932 0.335033 0 -0 0</wrench>
        </link>
        <link name='r_thumb_link'>
          <pose frame=''>0.019742 -0.144665 0.764766 0.000121 -7.8e-05 0.000333</pose>
          <velocity>-0.024973 0.044221 0.007216 0.242921 0.096874 -0.005999</velocity>
          <acceleration>-13.419 18.3914 30.0859 -1.60477 0.030199 -1.69747</acceleration>
          <wrench>-1.3419 1.83914 3.00859 0 -0 0</wrench>
        </link>
        <link name='r_upperarm_link'>
          <pose frame=''>0.01962 -0.167209 1.27241 0.000403 -0.000314 0.000288</pose>
          <velocity>0.000914 0.000641 0.000299 0.03116 0.040841 -0.007034</velocity>
          <acceleration>-0.424735 -31.5923 -4.02837 1.19568 0.794196 0.429506</acceleration>
          <wrench>-0.243798 -18.134 -2.31229 0 -0 0</wrench>
        </link>
        <link name='r_wrist_center'>
          <pose frame=''>0.019748 -0.167036 0.844407 0.000393 6e-06 0.000343</pose>
          <velocity>-0.017037 0.022724 0.002006 0.294856 0.103731 -0.006225</velocity>
          <acceleration>-8.21535 -52.6097 -3.99864 0.810566 -0.243896 -0.934326</acceleration>
          <wrench>-0.410768 -2.63049 -0.199932 0 -0 0</wrench>
        </link>
      </model>
      <model name='unit_box'>
        <pose frame=''>1.605 1.26727 0.499996 -7e-06 -0 -3e-06</pose>
        <scale>1 1 1</scale>
        <link name='link'>
          <pose frame=''>1.605 1.26727 0.499996 -7e-06 -0 -3e-06</pose>
          <velocity>0 0 0 0 -0 0</velocity>
          <acceleration>1.2e-05 3.66922 -3.66918 -1.05521 2.4e-05 -1.8e-05</acceleration>
          <wrench>1.2e-05 3.66922 -3.66918 0 -0 0</wrench>
        </link>
      </model>
      <light name='sun'>
        <pose frame=''>0 0 10 0 -0 0</pose>
      </light>
    </state>
    <gravity>0 0 -9.8</gravity>
    <magnetic_field>6e-06 2.3e-05 -4.2e-05</magnetic_field>
    <atmosphere type='adiabatic'/>
    <physics name='default_physics' default='0' type='ode'>
      <max_step_size>0.001</max_step_size>
      <real_time_factor>1</real_time_factor>
      <real_time_update_rate>1000</real_time_update_rate>
    </physics>
    <scene>
      <ambient>0.4 0.4 0.4 1</ambient>
      <background>0.7 0.7 0.7 1</background>
      <shadows>1</shadows>
    </scene>
    <audio>
      <device>default</device>
    </audio>
    <wind/>
    <spherical_coordinates>
      <surface_model>EARTH_WGS84</surface_model>
      <latitude_deg>0</latitude_deg>
      <longitude_deg>0</longitude_deg>
      <elevation>0</elevation>
      <heading_deg>0</heading_deg>
    </spherical_coordinates>
    <gui fullscreen='0'>
      <camera name='user_camera'>
        <pose frame=''>1.68266 0.78791 2.95412 -0 1.1018 -0.751781</pose>
        <view_controller>orbit</view_controller>
        <projection_type>perspective</projection_type>
      </camera>
    </gui>
    <model name='bookshelf'>
      <static>1</static>
      <link name='link'>
        <inertial>
          <mass>1</mass>
        </inertial>
        <collision name='back'>
          <pose frame=''>0 0.005 0.6 0 -0 0</pose>
          <geometry>
            <box>
              <size>0.9 0.01 1.2</size>
            </box>
          </geometry>
          <max_contacts>10</max_contacts>
          <surface>
            <contact>
              <ode/>
            </contact>
            <bounce/>
            <friction>
              <torsional>
                <ode/>
              </torsional>
              <ode/>
            </friction>
          </surface>
        </collision>
        <visual name='visual1'>
          <pose frame=''>0 0.005 0.6 0 -0 0</pose>
          <geometry>
            <box>
              <size>0.9 0.01 1.2</size>
            </box>
          </geometry>
          <material>
            <script>
              <uri>file://media/materials/scripts/gazebo.material</uri>
              <name>Gazebo/Wood</name>
            </script>
          </material>
        </visual>
        <collision name='left_side'>
          <pose frame=''>0.45 -0.195 0.6 0 -0 0</pose>
          <geometry>
            <box>
              <size>0.02 0.4 1.2</size>
            </box>
          </geometry>
          <max_contacts>10</max_contacts>
          <surface>
            <contact>
              <ode/>
            </contact>
            <bounce/>
            <friction>
              <torsional>
                <ode/>
              </torsional>
              <ode/>
            </friction>
          </surface>
        </collision>
        <visual name='visual2'>
          <pose frame=''>0.45 -0.195 0.6 0 -0 0</pose>
          <geometry>
            <box>
              <size>0.02 0.4 1.2</size>
            </box>
          </geometry>
          <material>
            <script>
              <uri>file://media/materials/scripts/gazebo.material</uri>
              <name>Gazebo/Wood</name>
            </script>
          </material>
        </visual>
        <collision name='right_side'>
          <pose frame=''>-0.45 -0.195 0.6 0 -0 0</pose>
          <geometry>
            <box>
              <size>0.02 0.4 1.2</size>
            </box>
          </geometry>
          <max_contacts>10</max_contacts>
          <surface>
            <contact>
              <ode/>
            </contact>
            <bounce/>
            <friction>
              <torsional>
                <ode/>
              </torsional>
              <ode/>
            </friction>
          </surface>
        </collision>
        <visual name='visual3'>
          <pose frame=''>-0.45 -0.195 0.6 0 -0 0</pose>
          <geometry>
            <box>
              <size>0.02 0.4 1.2</size>
            </box>
          </geometry>
          <material>
            <script>
              <uri>file://media/materials/scripts/gazebo.material</uri>
              <name>Gazebo/Wood</name>
            </script>
          </material>
        </visual>
        <collision name='bottom'>
          <pose frame=''>0 -0.195 0.03 0 -0 0</pose>
          <geometry>
            <box>
              <size>0.88 0.4 0.06</size>
            </box>
          </geometry>
          <max_contacts>10</max_contacts>
          <surface>
            <contact>
              <ode/>
            </contact>
            <bounce/>
            <friction>
              <torsional>
                <ode/>
              </torsional>
              <ode/>
            </friction>
          </surface>
        </collision>
        <visual name='visual4'>
          <pose frame=''>0 -0.195 0.03 0 -0 0</pose>
          <geometry>
            <box>
              <size>0.88 0.4 0.06</size>
            </box>
          </geometry>
          <material>
            <script>
              <uri>file://media/materials/scripts/gazebo.material</uri>
              <name>Gazebo/Wood</name>
            </script>
          </material>
        </visual>
        <collision name='top'>
          <pose frame=''>0 -0.195 1.19 0 -0 0</pose>
          <geometry>
            <box>
              <size>0.88 0.4 0.02</size>
            </box>
          </geometry>
          <max_contacts>10</max_contacts>
          <surface>
            <contact>
              <ode/>
            </contact>
            <bounce/>
            <friction>
              <torsional>
                <ode/>
              </torsional>
              <ode/>
            </friction>
          </surface>
        </collision>
        <visual name='visual5'>
          <pose frame=''>0 -0.195 1.19 0 -0 0</pose>
          <geometry>
            <box>
              <size>0.88 0.4 0.02</size>
            </box>
          </geometry>
          <material>
            <script>
              <uri>file://media/materials/scripts/gazebo.material</uri>
              <name>Gazebo/Wood</name>
            </script>
          </material>
        </visual>
        <collision name='low_shelf'>
          <pose frame=''>0 -0.195 0.43 0 -0 0</pose>
          <geometry>
            <box>
              <size>0.88 0.4 0.02</size>
            </box>
          </geometry>
          <max_contacts>10</max_contacts>
          <surface>
            <contact>
              <ode/>
            </contact>
            <bounce/>
            <friction>
              <torsional>
                <ode/>
              </torsional>
              <ode/>
            </friction>
          </surface>
        </collision>
        <visual name='visual6'>
          <pose frame=''>0 -0.195 0.43 0 -0 0</pose>
          <geometry>
            <box>
              <size>0.88 0.4 0.02</size>
            </box>
          </geometry>
          <material>
            <script>
              <uri>file://media/materials/scripts/gazebo.material</uri>
              <name>Gazebo/Wood</name>
            </script>
          </material>
        </visual>
        <collision name='high_shelf'>
          <pose frame=''>0 -0.195 0.8 0 -0 0</pose>
          <geometry>
            <box>
              <size>0.88 0.4 0.02</size>
            </box>
          </geometry>
          <max_contacts>10</max_contacts>
          <surface>
            <contact>
              <ode/>
            </contact>
            <bounce/>
            <friction>
              <torsional>
                <ode/>
              </torsional>
              <ode/>
            </friction>
          </surface>
        </collision>
        <visual name='visual7'>
          <pose frame=''>0 -0.195 0.8 0 -0 0</pose>
          <geometry>
            <box>
              <size>0.88 0.4 0.02</size>
            </box>
          </geometry>
          <material>
            <script>
              <uri>file://media/materials/scripts/gazebo.material</uri>
              <name>Gazebo/Wood</name>
            </script>
          </material>
        </visual>
        <self_collide>0</self_collide>
        <enable_wind>0</enable_wind>
        <kinematic>0</kinematic>
      </link>
      <pose frame=''>3.47257 0.400252 0 0 -0 0</pose>
    </model>
    <model name='grey_wall'>
      <static>1</static>
      <link name='link'>
        <pose frame=''>0 0 1.4 0 -0 0</pose>
        <collision name='collision'>
          <geometry>
            <box>
              <size>7.5 0.2 2.8</size>
            </box>
          </geometry>
          <max_contacts>10</max_contacts>
          <surface>
            <contact>
              <ode/>
            </contact>
            <bounce/>
            <friction>
              <torsional>
                <ode/>
              </torsional>
              <ode/>
            </friction>
          </surface>
        </collision>
        <visual name='visual'>
          <cast_shadows>0</cast_shadows>
          <geometry>
            <box>
              <size>7.5 0.2 2.8</size>
            </box>
          </geometry>
          <material>
            <script>
              <uri>model://grey_wall/materials/scripts</uri>
              <uri>model://grey_wall/materials/textures</uri>
              <name>vrc/grey_wall</name>
            </script>
          </material>
        </visual>
        <self_collide>0</self_collide>
        <enable_wind>0</enable_wind>
        <kinematic>0</kinematic>
      </link>
      <pose frame=''>2.17689 -1.15773 0 0 -0 0</pose>
    </model>
    <model name='grey_wall_0'>
      <static>1</static>
      <link name='link'>
        <pose frame=''>0 0 1.4 0 -0 0</pose>
        <collision name='collision'>
          <geometry>
            <box>
              <size>7.5 0.2 2.8</size>
            </box>
          </geometry>
          <max_contacts>10</max_contacts>
          <surface>
            <contact>
              <ode/>
            </contact>
            <bounce/>
            <friction>
              <torsional>
                <ode/>
              </torsional>
              <ode/>
            </friction>
          </surface>
        </collision>
        <visual name='visual'>
          <cast_shadows>0</cast_shadows>
          <geometry>
            <box>
              <size>7.5 0.2 2.8</size>
            </box>
          </geometry>
          <material>
            <script>
              <uri>model://grey_wall/materials/scripts</uri>
              <uri>model://grey_wall/materials/textures</uri>
              <name>vrc/grey_wall</name>
            </script>
          </material>
        </visual>
        <self_collide>0</self_collide>
        <enable_wind>0</enable_wind>
        <kinematic>0</kinematic>
      </link>
      <pose frame=''>2.24542 1.86727 0 0 -0 0</pose>
    </model>
    <model name='grey_wall_1'>
      <static>1</static>
      <link name='link'>
        <pose frame=''>0 0 1.4 0 -0 0</pose>
        <collision name='collision'>
          <geometry>
            <box>
              <size>7.5 0.2 2.8</size>
            </box>
          </geometry>
          <max_contacts>10</max_contacts>
          <surface>
            <contact>
              <ode/>
            </contact>
            <bounce/>
            <friction>
              <torsional>
                <ode/>
              </torsional>
              <ode/>
            </friction>
          </surface>
        </collision>
        <visual name='visual'>
          <cast_shadows>0</cast_shadows>
          <geometry>
            <box>
              <size>7.5 0.2 2.8</size>
            </box>
          </geometry>
          <material>
            <script>
              <uri>model://grey_wall/materials/scripts</uri>
              <uri>model://grey_wall/materials/textures</uri>
              <name>vrc/grey_wall</name>
            </script>
          </material>
        </visual>
        <self_collide>0</self_collide>
        <enable_wind>0</enable_wind>
        <kinematic>0</kinematic>
      </link>
      <pose frame=''>7.21347 0.665893 0 0 -0 0</pose>
    </model>
    <model name='grey_wall_1_clone'>
      <static>1</static>
      <link name='link'>
        <pose frame=''>0 0 1.4 0 -0 0</pose>
        <collision name='collision'>
          <geometry>
            <box>
              <size>7.5 0.2 2.8</size>
            </box>
          </geometry>
          <max_contacts>10</max_contacts>
          <surface>
            <contact>
              <ode/>
            </contact>
            <bounce/>
            <friction>
              <torsional>
                <ode/>
              </torsional>
              <ode/>
            </friction>
          </surface>
        </collision>
        <visual name='visual'>
          <cast_shadows>0</cast_shadows>
          <geometry>
            <box>
              <size>7.5 0.2 2.8</size>
            </box>
          </geometry>
          <material>
            <script>
              <uri>model://grey_wall/materials/scripts</uri>
              <uri>model://grey_wall/materials/textures</uri>
              <name>vrc/grey_wall</name>
            </script>
          </material>
        </visual>
        <self_collide>0</self_collide>
        <enable_wind>0</enable_wind>
        <kinematic>0</kinematic>
      </link>
      <pose frame=''>-1.49276 0.228869 0 0 -0 1.57</pose>
    </model>
    <model name='unit_box'>
      <pose frame=''>1.605 1.4001 0.5 0 -0 0</pose>
      <link name='link'>
        <inertial>
          <mass>1</mass>
          <inertia>
            <ixx>0.166667</ixx>
            <ixy>0</ixy>
            <ixz>0</ixz>
            <iyy>0.166667</iyy>
            <iyz>0</iyz>
            <izz>0.166667</izz>
          </inertia>
        </inertial>
        <collision name='collision'>
          <geometry>
            <box>
              <size>1 1 1</size>
            </box>
          </geometry>
          <max_contacts>10</max_contacts>
          <surface>
            <contact>
              <ode/>
            </contact>
            <bounce/>
            <friction>
              <torsional>
                <ode/>
              </torsional>
              <ode/>
            </friction>
          </surface>
        </collision>
        <visual name='visual'>
          <geometry>
            <box>
              <size>1 1 1</size>
            </box>
          </geometry>
          <material>
            <script>
              <name>Gazebo/Grey</name>
              <uri>file://media/materials/scripts/gazebo.material</uri>
            </script>
          </material>
        </visual>
        <self_collide>0</self_collide>
        <enable_wind>0</enable_wind>
        <kinematic>0</kinematic>
      </link>
    </model>
    <model name='marker005_clone'>
      <pose frame=''>3.0108 0.581838 0.230018 0 1.57 0</pose>
      <link name='link'>
        <inertial>
          <mass>1</mass>
          <inertia>
            <ixx>0.083</ixx>
            <ixy>0</ixy>
            <ixz>0</ixz>
            <iyy>0.083</iyy>
            <iyz>0</iyz>
            <izz>0.083</izz>
          </inertia>
        </inertial>
        <collision name='collision'>
          <geometry>
            <box>
              <size>0.11 0.11 0.004</size>
            </box>
          </geometry>
          <max_contacts>10</max_contacts>
          <surface>
            <contact>
              <ode/>
            </contact>
            <bounce/>
            <friction>
              <torsional>
                <ode/>
              </torsional>
              <ode/>
            </friction>
          </surface>
        </collision>
        <visual name='visual'>
          <geometry>
            <box>
              <size>0.11 0.11 0.004</size>
            </box>
          </geometry>
          <material>
            <script>
              <uri>model://marker005/materials/marker005.material</uri>
              <name>marker005</name>
            </script>
          </material>
        </visual>
        <self_collide>0</self_collide>
        <enable_wind>0</enable_wind>
        <kinematic>0</kinematic>
      </link>
      <static>1</static>
    </model>
    <model name='marker006_clone'>
      <pose frame=''>2.993 -0.619714 0.23 0 1.57 0</pose>
      <link name='link'>
        <inertial>
          <mass>1</mass>
          <inertia>
            <ixx>0.083</ixx>
            <ixy>0</ixy>
            <ixz>0</ixz>
            <iyy>0.083</iyy>
            <iyz>0</iyz>
            <izz>0.083</izz>
          </inertia>
        </inertial>
        <collision name='collision'>
          <geometry>
            <box>
              <size>0.11 0.11 0.004</size>
            </box>
          </geometry>
          <max_contacts>10</max_contacts>
          <surface>
            <contact>
              <ode/>
            </contact>
            <bounce/>
            <friction>
              <torsional>
                <ode/>
              </torsional>
              <ode/>
            </friction>
          </surface>
        </collision>
        <visual name='visual'>
          <geometry>
            <box>
              <size>0.11 0.11 0.004</size>
            </box>
          </geometry>
          <material>
            <script>
              <uri>model://marker006/materials/marker006.material</uri>
              <name>marker006</name>
            </script>
          </material>
        </visual>
        <self_collide>0</self_collide>
        <enable_wind>0</enable_wind>
        <kinematic>0</kinematic>
      </link>
      <static>1</static>
    </model>
    <model name='seed_r7'>
      <link name='base_link'>
        <pose frame=''>0 0 0 0 -0 0</pose>
        <inertial>
          <pose frame=''>-0.000483 -0.000247 0.122246 0 -0 0</pose>
          <mass>82.846</mass>
          <inertia>
            <ixx>3.50606</ixx>
            <ixy>-0.000412149</ixy>
            <ixz>0.0130014</ixz>
            <iyy>12.4814</iyy>
            <iyz>0.00181134</iyz>
            <izz>14.5877</izz>
          </inertia>
        </inertial>
        <collision name='base_link_fixed_joint_lump__wheel_base_link_collision'>
          <pose frame=''>0.018 0 0.1125 0 -0 0</pose>
          <geometry>
            <box>
              <size>0.72 0.52 0.149</size>
            </box>
          </geometry>
          <surface>
            <contact>
              <ode/>
            </contact>
            <friction>
              <ode>
                <mu>0.9</mu>
                <mu2>0.9</mu2>
              </ode>
              <torsional>
                <ode/>
              </torsional>
            </friction>
            <bounce/>
          </surface>
          <max_contacts>10</max_contacts>
        </collision>
        <collision name='base_link_fixed_joint_lump__wheels_base_laser_link_collision_1'>
          <pose frame=''>0.29 0 0.195 0 -0 0</pose>
          <geometry>
            <box>
              <size>0.08 0.1 0.07</size>
            </box>
          </geometry>
          <surface>
            <contact>
              <ode/>
            </contact>
            <friction>
              <ode>
                <mu>0.9</mu>
                <mu2>0.9</mu2>
              </ode>
              <torsional>
                <ode/>
              </torsional>
            </friction>
            <bounce/>
          </surface>
          <max_contacts>10</max_contacts>
        </collision>
        <collision name='base_link_fixed_joint_lump__wheels_front_left_mecanum_collision_2'>
          <pose frame=''>0.2265 0.19485 0.075 -1.5708 0 0</pose>
          <geometry>
            <box>
              <size>0.152 0.152 0.046</size>
            </box>
          </geometry>
          <surface>
            <contact>
              <ode/>
            </contact>
            <friction>
              <ode>
                <mu>0.25</mu>
                <mu2>0.25</mu2>
              </ode>
              <torsional>
                <ode/>
              </torsional>
            </friction>
            <bounce/>
          </surface>
          <max_contacts>10</max_contacts>
        </collision>
        <collision name='base_link_fixed_joint_lump__wheels_front_right_mecanum_collision_3'>
          <pose frame=''>0.2265 -0.19485 0.075 -1.5708 0 0</pose>
          <geometry>
            <box>
              <size>0.152 0.152 0.046</size>
            </box>
          </geometry>
          <max_contacts>10</max_contacts>
          <surface>
            <contact>
              <ode/>
            </contact>
            <bounce/>
            <friction>
              <torsional>
                <ode/>
              </torsional>
              <ode/>
            </friction>
          </surface>
        </collision>
        <collision name='base_link_fixed_joint_lump__wheels_rear_left_mecanum_collision_4'>
          <pose frame=''>-0.2265 0.19485 0.075 -1.5708 0 0</pose>
          <geometry>
            <box>
              <size>0.152 0.152 0.046</size>
            </box>
          </geometry>
          <surface>
            <contact>
              <ode/>
            </contact>
            <friction>
              <ode>
                <mu>0.25</mu>
                <mu2>0.25</mu2>
              </ode>
              <torsional>
                <ode/>
              </torsional>
            </friction>
            <bounce/>
          </surface>
          <max_contacts>10</max_contacts>
        </collision>
        <collision name='base_link_fixed_joint_lump__wheels_rear_right_mecanum_collision_5'>
          <pose frame=''>-0.2265 -0.19485 0.075 -1.5708 0 0</pose>
          <geometry>
            <box>
              <size>0.152 0.152 0.046</size>
            </box>
          </geometry>
          <surface>
            <contact>
              <ode/>
            </contact>
            <friction>
              <ode>
                <mu>0.25</mu>
                <mu2>0.25</mu2>
              </ode>
              <torsional>
                <ode/>
              </torsional>
            </friction>
            <bounce/>
          </surface>
          <max_contacts>10</max_contacts>
        </collision>
        <collision name='base_link_fixed_joint_lump__lifter_base_link_collision_6'>
          <pose frame=''>0 0 0.195 0 -0 0</pose>
          <geometry>
            <mesh>
              <scale>1 1 1</scale>
              <uri>/home/rsdlab/catkin_ws/src/seed_r7_ros_pkg/seed_r7_description/meshes/typeC_lifter/lifter_base.dae</uri>
            </mesh>
          </geometry>
          <surface>
            <contact>
              <ode/>
            </contact>
            <friction>
              <ode>
                <mu>0.9</mu>
                <mu2>0.9</mu2>
              </ode>
              <torsional>
                <ode/>
              </torsional>
            </friction>
            <bounce/>
          </surface>
          <max_contacts>10</max_contacts>
        </collision>
        <visual name='base_link_fixed_joint_lump__wheel_base_link_visual'>
          <pose frame=''>0 0 0.075 0 -0 0</pose>
          <geometry>
            <mesh>
              <scale>1 1 1</scale>
              <uri>/home/rsdlab/catkin_ws/src/seed_r7_ros_pkg/seed_r7_description/meshes/typeE_wheel/wheels_base.dae</uri>
            </mesh>
          </geometry>
          <material>
            <script>
              <uri>__default__</uri>
              <name>__default__</name>
            </script>
          </material>
        </visual>
        <visual name='base_link_fixed_joint_lump__wheels_base_laser_link_visual_1'>
          <pose frame=''>0.29 0 0.2074 0 -0 0</pose>
          <geometry>
            <mesh>
              <scale>1 1 1</scale>
              <uri>/home/rsdlab/catkin_ws/src/seed_r7_ros_pkg/seed_r7_description/meshes/typeE_wheel/wheels_urg.dae</uri>
            </mesh>
          </geometry>
          <material>
            <script>
              <uri>__default__</uri>
              <name>__default__</name>
            </script>
          </material>
        </visual>
        <visual name='base_link_fixed_joint_lump__wheels_front_left_mecanum_visual_2'>
          <pose frame=''>0.2265 0.19485 0.075 -1.5708 0 0</pose>
          <geometry>
            <mesh>
              <scale>1 1 1</scale>
              <uri>/home/rsdlab/catkin_ws/src/seed_r7_ros_pkg/seed_r7_description/meshes/typeE_wheel/wheels_mecanum.dae</uri>
            </mesh>
          </geometry>
          <material>
            <script>
              <uri>__default__</uri>
              <name>__default__</name>
            </script>
          </material>
        </visual>
        <visual name='base_link_fixed_joint_lump__wheels_front_right_mecanum_visual_3'>
          <pose frame=''>0.2265 -0.19485 0.075 -1.5708 0 0</pose>
          <geometry>
            <mesh>
              <scale>1 1 1</scale>
              <uri>/home/rsdlab/catkin_ws/src/seed_r7_ros_pkg/seed_r7_description/meshes/typeE_wheel/wheels_mecanum.dae</uri>
            </mesh>
          </geometry>
        </visual>
        <visual name='base_link_fixed_joint_lump__wheels_rear_left_mecanum_visual_4'>
          <pose frame=''>-0.2265 0.19485 0.075 -1.5708 0 0</pose>
          <geometry>
            <mesh>
              <scale>1 1 1</scale>
              <uri>/home/rsdlab/catkin_ws/src/seed_r7_ros_pkg/seed_r7_description/meshes/typeE_wheel/wheels_mecanum.dae</uri>
            </mesh>
          </geometry>
          <material>
            <script>
              <uri>__default__</uri>
              <name>__default__</name>
            </script>
          </material>
        </visual>
        <visual name='base_link_fixed_joint_lump__wheels_rear_right_mecanum_visual_5'>
          <pose frame=''>-0.2265 -0.19485 0.075 -1.5708 0 0</pose>
          <geometry>
            <mesh>
              <scale>1 1 1</scale>
              <uri>/home/rsdlab/catkin_ws/src/seed_r7_ros_pkg/seed_r7_description/meshes/typeE_wheel/wheels_mecanum.dae</uri>
            </mesh>
          </geometry>
          <material>
            <script>
              <uri>__default__</uri>
              <name>__default__</name>
            </script>
          </material>
        </visual>
        <visual name='base_link_fixed_joint_lump__wheels_top_link_visual_6'>
          <pose frame=''>0 0 0.19 0 -0 0</pose>
          <geometry>
            <mesh>
              <scale>1 1 1</scale>
              <uri>/home/rsdlab/catkin_ws/src/seed_r7_ros_pkg/seed_r7_description/meshes/typeE_wheel/wheels_top.dae</uri>
            </mesh>
          </geometry>
          <material>
            <script>
              <uri>__default__</uri>
              <name>__default__</name>
            </script>
          </material>
        </visual>
        <visual name='base_link_fixed_joint_lump__lifter_base_link_visual_7'>
          <pose frame=''>0 0 0.195 0 -0 0</pose>
          <geometry>
            <mesh>
              <scale>1 1 1</scale>
              <uri>/home/rsdlab/catkin_ws/src/seed_r7_ros_pkg/seed_r7_description/meshes/typeC_lifter/lifter_base.dae</uri>
            </mesh>
          </geometry>
          <material>
            <script>
              <uri>__default__</uri>
              <name>__default__</name>
            </script>
          </material>
        </visual>
        <velocity_decay/>
        <velocity_decay/>
        <velocity_decay/>
        <sensor name='head_hokuyo_sensor' type='ray'>
          <visualize>0</visualize>
          <update_rate>10</update_rate>
          <ray>
            <scan>
              <horizontal>
                <samples>1000</samples>
                <resolution>1</resolution>
                <min_angle>-2.35619</min_angle>
                <max_angle>2.35619</max_angle>
              </horizontal>
              <vertical>
                <samples>1</samples>
                <min_angle>0</min_angle>
                <max_angle>0</max_angle>
              </vertical>
            </scan>
            <range>
              <min>0.08</min>
              <max>20</max>
              <resolution>0.01</resolution>
            </range>
            <noise>
              <type>gaussian</type>
              <mean>0</mean>
              <stddev>0.01</stddev>
            </noise>
          </ray>
          <plugin name='gazebo_ros_head_hokuyo_controller' filename='libgazebo_ros_laser.so'>
            <topicName>scan</topicName>
            <frameName>wheels_base_laser_link</frameName>
            <robotNamespace>/</robotNamespace>
          </plugin>
          <pose frame=''>0.29 0 0.2074 0 -0 0</pose>
        </sensor>
        <velocity_decay/>
        <velocity_decay/>
        <velocity_decay/>
        <velocity_decay/>
        <velocity_decay/>
        <velocity_decay/>
        <gravity>1</gravity>
        <velocity_decay/>
        <gravity>1</gravity>
        <sensor name='imu_sensor' type='imu'>
          <always_on>1</always_on>
          <update_rate>100</update_rate>
          <visualize>1</visualize>
          <topic>imu</topic>
          <plugin name='imu_plugin' filename='libgazebo_ros_imu_sensor.so'>
            <topicName>imu</topicName>
            <bodyName>imu_link</bodyName>
            <updateRateHZ>10.0</updateRateHZ>
            <gaussianNoise>0.0</gaussianNoise>
            <xyzOffset>0 0 0</xyzOffset>
            <rpyOffset>0 0 0</rpyOffset>
            <frameName>imu_link</frameName>
            <initialOrientationAsReference>0</initialOrientationAsReference>
            <robotNamespace>/</robotNamespace>
          </plugin>
          <pose frame=''>0 0 0.068 0 -0 0</pose>
          <imu/>
        </sensor>
        <self_collide>0</self_collide>
        <enable_wind>0</enable_wind>
        <kinematic>0</kinematic>
      </link>
      <link name='leg_shank_link'>
        <pose frame=''>0 0 0.245 0 -0 0</pose>
        <inertial>
          <pose frame=''>0.051713 0 0.146934 0 -0 0</pose>
          <mass>2.06679</mass>
          <inertia>
            <ixx>0.06</ixx>
            <ixy>0</ixy>
            <ixz>0</ixz>
            <iyy>0.1</iyy>
            <iyz>0</iyz>
            <izz>0.06</izz>
          </inertia>
        </inertial>
        <collision name='leg_shank_link_collision'>
          <pose frame=''>0 0 0 3.1415 -0 0</pose>
          <geometry>
            <mesh>
              <scale>1 1 1</scale>
              <uri>/home/rsdlab/catkin_ws/src/seed_r7_ros_pkg/seed_r7_description/meshes/typeC_lifter/lifter_bone.dae</uri>
            </mesh>
          </geometry>
          <surface>
            <contact>
              <ode/>
            </contact>
            <friction>
              <ode>
                <mu>0.9</mu>
                <mu2>0.9</mu2>
              </ode>
              <torsional>
                <ode/>
              </torsional>
            </friction>
            <bounce/>
          </surface>
          <max_contacts>10</max_contacts>
        </collision>
        <visual name='leg_shank_link_visual'>
          <pose frame=''>0 0 0 3.1415 -0 0</pose>
          <geometry>
            <mesh>
              <scale>1 1 1</scale>
              <uri>/home/rsdlab/catkin_ws/src/seed_r7_ros_pkg/seed_r7_description/meshes/typeC_lifter/lifter_bone.dae</uri>
            </mesh>
          </geometry>
          <material>
            <script>
              <uri>__default__</uri>
              <name>__default__</name>
            </script>
          </material>
        </visual>
        <gravity>1</gravity>
        <velocity_decay/>
        <self_collide>0</self_collide>
        <enable_wind>0</enable_wind>
        <kinematic>0</kinematic>
      </link>
      <joint name='ankle_joint' type='revolute'>
        <child>leg_shank_link</child>
        <parent>base_link</parent>
        <axis>
          <xyz>0 -1 0</xyz>
          <limit>
            <lower>0</lower>
            <upper>1.5707</upper>
            <effort>1000</effort>
            <velocity>0.5</velocity>
          </limit>
          <dynamics>
            <damping>0.2</damping>
            <friction>0</friction>
            <spring_reference>0</spring_reference>
            <spring_stiffness>0</spring_stiffness>
          </dynamics>
          <use_parent_model_frame>1</use_parent_model_frame>
        </axis>
        <physics>
          <ode>
            <implicit_spring_damper>0</implicit_spring_damper>
            <cfm_damping>0</cfm_damping>
            <limit>
              <cfm>0</cfm>
              <erp>0.2</erp>
            </limit>
          </ode>
        </physics>
      </joint>
      <link name='leg_knee_link'>
        <pose frame=''>0 0 0.495 0 -0 0</pose>
        <inertial>
          <pose frame=''>-0.031713 0 0.046934 0 -0 0</pose>
          <mass>2.06679</mass>
          <inertia>
            <ixx>0.06</ixx>
            <ixy>0</ixy>
            <ixz>0</ixz>
            <iyy>0.1</iyy>
            <iyz>0</iyz>
            <izz>0.06</izz>
          </inertia>
        </inertial>
        <collision name='leg_knee_link_collision'>
          <pose frame=''>0 0 0 3.1415 -0 0</pose>
          <geometry>
            <mesh>
              <scale>1 1 1</scale>
              <uri>/home/rsdlab/catkin_ws/src/seed_r7_ros_pkg/seed_r7_description/meshes/typeC_lifter/lifter_knee.dae</uri>
            </mesh>
          </geometry>
          <surface>
            <contact>
              <ode/>
            </contact>
            <friction>
              <ode>
                <mu>0.9</mu>
                <mu2>0.9</mu2>
              </ode>
              <torsional>
                <ode/>
              </torsional>
            </friction>
            <bounce/>
          </surface>
          <max_contacts>10</max_contacts>
        </collision>
        <visual name='leg_knee_link_visual'>
          <pose frame=''>0 0 0 3.1415 -0 0</pose>
          <geometry>
            <mesh>
              <scale>1 1 1</scale>
              <uri>/home/rsdlab/catkin_ws/src/seed_r7_ros_pkg/seed_r7_description/meshes/typeC_lifter/lifter_knee.dae</uri>
            </mesh>
          </geometry>
          <material>
            <script>
              <uri>__default__</uri>
              <name>__default__</name>
            </script>
          </material>
        </visual>
        <gravity>1</gravity>
        <velocity_decay/>
        <self_collide>0</self_collide>
        <enable_wind>0</enable_wind>
        <kinematic>0</kinematic>
      </link>
      <joint name='ankle_joint_mimic' type='revolute'>
        <child>leg_knee_link</child>
        <parent>leg_shank_link</parent>
        <axis>
          <xyz>0 -1 0</xyz>
          <limit>
            <lower>-1e+16</lower>
            <upper>1e+16</upper>
          </limit>
          <dynamics>
            <spring_reference>0</spring_reference>
            <spring_stiffness>0</spring_stiffness>
          </dynamics>
          <use_parent_model_frame>1</use_parent_model_frame>
        </axis>
      </joint>
      <link name='leg_thigh_link'>
        <pose frame=''>0 0 0.615 0 -0 0</pose>
        <inertial>
          <pose frame=''>-0.058717 0 0.135292 0 -0 0</pose>
          <mass>2.62321</mass>
          <inertia>
            <ixx>0.0161595</ixx>
            <ixy>-9.27234e-05</ixy>
            <ixz>0.00262839</ixz>
            <iyy>0.0166415</iyy>
            <iyz>-0.00017447</iyz>
            <izz>0.00477281</izz>
          </inertia>
        </inertial>
        <collision name='leg_thigh_link_collision'>
          <pose frame=''>0 0 0.25 0 -0 0</pose>
          <geometry>
            <mesh>
              <scale>1 1 1</scale>
              <uri>/home/rsdlab/catkin_ws/src/seed_r7_ros_pkg/seed_r7_description/meshes/typeC_lifter/lifter_bone.dae</uri>
            </mesh>
          </geometry>
          <surface>
            <contact>
              <ode/>
            </contact>
            <friction>
              <ode>
                <mu>0.9</mu>
                <mu2>0.9</mu2>
              </ode>
              <torsional>
                <ode/>
              </torsional>
            </friction>
            <bounce/>
          </surface>
          <max_contacts>10</max_contacts>
        </collision>
        <visual name='leg_thigh_link_visual'>
          <pose frame=''>0 0 0.25 0 -0 0</pose>
          <geometry>
            <mesh>
              <scale>1 1 1</scale>
              <uri>/home/rsdlab/catkin_ws/src/seed_r7_ros_pkg/seed_r7_description/meshes/typeC_lifter/lifter_bone.dae</uri>
            </mesh>
          </geometry>
          <material>
            <script>
              <uri>__default__</uri>
              <name>__default__</name>
            </script>
          </material>
        </visual>
        <gravity>1</gravity>
        <velocity_decay/>
        <self_collide>0</self_collide>
        <enable_wind>0</enable_wind>
        <kinematic>0</kinematic>
      </link>
      <joint name='knee_joint' type='revolute'>
        <child>leg_thigh_link</child>
        <parent>leg_knee_link</parent>
        <axis>
          <xyz>0 -1 0</xyz>
          <limit>
            <lower>-1.5707</lower>
            <upper>0</upper>
            <effort>1000</effort>
            <velocity>0.5</velocity>
          </limit>
          <dynamics>
            <spring_reference>0</spring_reference>
            <spring_stiffness>0</spring_stiffness>
          </dynamics>
          <use_parent_model_frame>1</use_parent_model_frame>
        </axis>
        <physics>
          <ode>
            <implicit_spring_damper>0</implicit_spring_damper>
            <cfm_damping>0</cfm_damping>
            <limit>
              <cfm>0</cfm>
              <erp>0.2</erp>
            </limit>
          </ode>
        </physics>
      </joint>
      <link name='leg_base_link'>
        <pose frame=''>0 0 0.865 0 -0 0</pose>
        <inertial>
          <pose frame=''>-0.009897 -0.002068 0.0181 0 -0 0</pose>
          <mass>9.90304</mass>
          <inertia>
            <ixx>0.133807</ixx>
            <ixy>-0.000219307</ixy>
            <ixz>0.00903538</ixz>
            <iyy>0.118694</iyy>
            <iyz>-4.9684e-05</iyz>
            <izz>0.147276</izz>
          </inertia>
        </inertial>
        <collision name='leg_base_link_collision'>
          <pose frame=''>0 0 0.05 3.14159 -0 0</pose>
          <geometry>
            <mesh>
              <scale>1 1 1</scale>
              <uri>/home/rsdlab/catkin_ws/src/seed_r7_ros_pkg/seed_r7_description/meshes/typeC_lifter/lifter_base.dae</uri>
            </mesh>
          </geometry>
          <surface>
            <contact>
              <ode/>
            </contact>
            <friction>
              <ode>
                <mu>0.9</mu>
                <mu2>0.9</mu2>
              </ode>
              <torsional>
                <ode/>
              </torsional>
            </friction>
            <bounce/>
          </surface>
          <max_contacts>10</max_contacts>
        </collision>
        <collision name='leg_base_link_fixed_joint_lump__lifter_top_link_collision_1'>
          <pose frame=''>0 0 0.055 0 -0 0</pose>
          <geometry>
            <mesh>
              <scale>1 1 1</scale>
              <uri>/home/rsdlab/catkin_ws/src/seed_r7_ros_pkg/seed_r7_description/meshes/typeC_lifter/lifter_top.dae</uri>
            </mesh>
          </geometry>
          <surface>
            <contact>
              <ode/>
            </contact>
            <friction>
              <ode>
                <mu>0.9</mu>
                <mu2>0.9</mu2>
              </ode>
              <torsional>
                <ode/>
              </torsional>
            </friction>
            <bounce/>
          </surface>
          <max_contacts>10</max_contacts>
        </collision>
        <collision name='leg_base_link_fixed_joint_lump__waist_link_collision_2'>
          <pose frame=''>0 0 0.055 0 -0 0</pose>
          <geometry>
            <mesh>
              <scale>1 1 1</scale>
              <uri>/home/rsdlab/catkin_ws/src/seed_r7_ros_pkg/seed_r7_description/meshes/typeF_upperbody/WAIST_LINK0_mesh.dae</uri>
            </mesh>
          </geometry>
          <surface>
            <contact>
              <ode/>
            </contact>
            <friction>
              <ode>
                <mu>0.9</mu>
                <mu2>0.9</mu2>
              </ode>
              <torsional>
                <ode/>
              </torsional>
            </friction>
            <bounce/>
          </surface>
          <max_contacts>10</max_contacts>
        </collision>
        <visual name='leg_base_link_visual'>
          <pose frame=''>0 0 0.05 3.14159 -0 0</pose>
          <geometry>
            <mesh>
              <scale>1 1 1</scale>
              <uri>/home/rsdlab/catkin_ws/src/seed_r7_ros_pkg/seed_r7_description/meshes/typeC_lifter/lifter_base.dae</uri>
            </mesh>
          </geometry>
          <material>
            <script>
              <uri>__default__</uri>
              <name>__default__</name>
            </script>
          </material>
        </visual>
        <visual name='leg_base_link_fixed_joint_lump__lifter_top_link_visual_1'>
          <pose frame=''>0 0 0.055 0 -0 0</pose>
          <geometry>
            <mesh>
              <scale>1 1 1</scale>
              <uri>/home/rsdlab/catkin_ws/src/seed_r7_ros_pkg/seed_r7_description/meshes/typeC_lifter/lifter_top.dae</uri>
            </mesh>
          </geometry>
          <material>
            <script>
              <uri>__default__</uri>
              <name>__default__</name>
            </script>
          </material>
        </visual>
        <visual name='leg_base_link_fixed_joint_lump__waist_link_visual_2'>
          <pose frame=''>0 0 0.055 0 -0 0</pose>
          <geometry>
            <mesh>
              <scale>1 1 1</scale>
              <uri>/home/rsdlab/catkin_ws/src/seed_r7_ros_pkg/seed_r7_description/meshes/typeF_upperbody/WAIST_LINK0_mesh.dae</uri>
            </mesh>
          </geometry>
          <material>
            <script>
              <uri>__default__</uri>
              <name>__default__</name>
            </script>
          </material>
        </visual>
        <velocity_decay/>
        <velocity_decay/>
        <gravity>1</gravity>
        <velocity_decay/>
        <self_collide>0</self_collide>
        <enable_wind>0</enable_wind>
        <kinematic>0</kinematic>
      </link>
      <joint name='knee_joint_mimic' type='revolute'>
        <child>leg_base_link</child>
        <parent>leg_thigh_link</parent>
        <axis>
          <xyz>0 -1 0</xyz>
          <limit>
            <lower>-1e+16</lower>
            <upper>1e+16</upper>
          </limit>
          <dynamics>
            <spring_reference>0</spring_reference>
            <spring_stiffness>0</spring_stiffness>
          </dynamics>
          <use_parent_model_frame>1</use_parent_model_frame>
        </axis>
      </joint>
      <link name='hip_sphere_link'>
        <pose frame=''>0 0 0.93 0 -0 0</pose>
        <inertial>
          <pose frame=''>0 0 0.042 0 -0 0</pose>
          <mass>1.257</mass>
          <inertia>
            <ixx>0.01</ixx>
            <ixy>0</ixy>
            <ixz>0</ixz>
            <iyy>0.01</iyy>
            <iyz>0</iyz>
            <izz>0.007</izz>
          </inertia>
        </inertial>
        <collision name='hip_sphere_link_collision'>
          <pose frame=''>0 0 0 0 -0 0</pose>
          <geometry>
            <mesh>
              <scale>1 1 1</scale>
              <uri>/home/rsdlab/catkin_ws/src/seed_r7_ros_pkg/seed_r7_description/meshes/typeF_upperbody/WAIST_LINK1_mesh.dae</uri>
            </mesh>
          </geometry>
          <surface>
            <contact>
              <ode/>
            </contact>
            <friction>
              <ode>
                <mu>0.9</mu>
                <mu2>0.9</mu2>
              </ode>
              <torsional>
                <ode/>
              </torsional>
            </friction>
            <bounce/>
          </surface>
          <max_contacts>10</max_contacts>
        </collision>
        <visual name='hip_sphere_link_visual'>
          <pose frame=''>0 0 0 0 -0 0</pose>
          <geometry>
            <mesh>
              <scale>1 1 1</scale>
              <uri>/home/rsdlab/catkin_ws/src/seed_r7_ros_pkg/seed_r7_description/meshes/typeF_upperbody/WAIST_LINK1_mesh.dae</uri>
            </mesh>
          </geometry>
          <material>
            <script>
              <uri>__default__</uri>
              <name>__default__</name>
            </script>
          </material>
        </visual>
        <gravity>1</gravity>
        <velocity_decay/>
        <self_collide>0</self_collide>
        <enable_wind>0</enable_wind>
        <kinematic>0</kinematic>
      </link>
      <joint name='waist_y_joint' type='revolute'>
        <child>hip_sphere_link</child>
        <parent>leg_base_link</parent>
        <axis>
          <xyz>0 0 1</xyz>
          <limit>
            <lower>-2.09</lower>
            <upper>2.09</upper>
            <effort>100</effort>
            <velocity>0.6</velocity>
          </limit>
          <dynamics>
            <damping>0.2</damping>
            <friction>0</friction>
            <spring_reference>0</spring_reference>
            <spring_stiffness>0</spring_stiffness>
          </dynamics>
          <use_parent_model_frame>1</use_parent_model_frame>
        </axis>
        <physics>
          <ode>
            <implicit_spring_damper>0</implicit_spring_damper>
            <cfm_damping>0</cfm_damping>
            <limit>
              <cfm>0</cfm>
              <erp>0.2</erp>
            </limit>
          </ode>
        </physics>
      </joint>
      <link name='hip_center'>
        <pose frame=''>0 0 1.0655 0 -0 0</pose>
        <inertial>
          <pose frame=''>0 0 0 0 -0 0</pose>
          <mass>0.1</mass>
          <inertia>
            <ixx>0.003</ixx>
            <ixy>0</ixy>
            <ixz>0</ixz>
            <iyy>0.003</iyy>
            <iyz>0</iyz>
            <izz>0.003</izz>
          </inertia>
        </inertial>
        <gravity>1</gravity>
        <velocity_decay/>
        <self_collide>0</self_collide>
        <enable_wind>0</enable_wind>
        <kinematic>0</kinematic>
      </link>
      <joint name='waist_p_joint' type='revolute'>
        <child>hip_center</child>
        <parent>hip_sphere_link</parent>
        <axis>
          <xyz>0 1 0</xyz>
          <limit>
            <lower>-0.087</lower>
            <upper>0.61</upper>
            <effort>100</effort>
            <velocity>0.5</velocity>
          </limit>
          <dynamics>
            <damping>0.2</damping>
            <friction>0</friction>
            <spring_reference>0</spring_reference>
            <spring_stiffness>0</spring_stiffness>
          </dynamics>
          <use_parent_model_frame>1</use_parent_model_frame>
        </axis>
        <physics>
          <ode>
            <implicit_spring_damper>0</implicit_spring_damper>
            <cfm_damping>0</cfm_damping>
            <limit>
              <cfm>0</cfm>
              <erp>0.2</erp>
            </limit>
          </ode>
        </physics>
      </joint>
      <link name='body_link'>
        <pose frame=''>0 0 1.0655 0 -0 0</pose>
        <inertial>
          <pose frame=''>0 0 0.22 0 -0 0</pose>
          <mass>10.551</mass>
          <inertia>
            <ixx>0.13</ixx>
            <ixy>0</ixy>
            <ixz>0</ixz>
            <iyy>0.12</iyy>
            <iyz>0</iyz>
            <izz>0.114</izz>
          </inertia>
        </inertial>
        <collision name='body_link_collision'>
          <pose frame=''>0 0 0 0 -0 0</pose>
          <geometry>
            <mesh>
              <scale>1 1 1</scale>
              <uri>/home/rsdlab/catkin_ws/src/seed_r7_ros_pkg/seed_r7_description/meshes/typeF_upperbody/WAIST_LINK3_mesh.dae</uri>
            </mesh>
          </geometry>
          <surface>
            <contact>
              <ode/>
            </contact>
            <friction>
              <ode>
                <mu>0.9</mu>
                <mu2>0.9</mu2>
              </ode>
              <torsional>
                <ode/>
              </torsional>
            </friction>
            <bounce/>
          </surface>
          <max_contacts>10</max_contacts>
        </collision>
        <visual name='body_link_visual'>
          <pose frame=''>0 0 0 0 -0 0</pose>
          <geometry>
            <mesh>
              <scale>1 1 1</scale>
              <uri>/home/rsdlab/catkin_ws/src/seed_r7_ros_pkg/seed_r7_description/meshes/typeF_upperbody/WAIST_LINK3_mesh.dae</uri>
            </mesh>
          </geometry>
          <material>
            <script>
              <uri>__default__</uri>
              <name>__default__</name>
            </script>
          </material>
        </visual>
        <gravity>1</gravity>
        <velocity_decay/>
        <self_collide>0</self_collide>
        <enable_wind>0</enable_wind>
        <kinematic>0</kinematic>
      </link>
      <joint name='waist_r_joint' type='revolute'>
        <child>body_link</child>
        <parent>hip_center</parent>
        <axis>
          <xyz>1 0 0</xyz>
          <limit>
            <lower>-0.017</lower>
            <upper>0.017</upper>
            <effort>100</effort>
            <velocity>0.4</velocity>
          </limit>
          <dynamics>
            <damping>0.2</damping>
            <friction>0</friction>
            <spring_reference>0</spring_reference>
            <spring_stiffness>0</spring_stiffness>
          </dynamics>
          <use_parent_model_frame>1</use_parent_model_frame>
        </axis>
        <physics>
          <ode>
            <implicit_spring_damper>0</implicit_spring_damper>
            <cfm_damping>0</cfm_damping>
            <limit>
              <cfm>0</cfm>
              <erp>0.2</erp>
            </limit>
          </ode>
        </physics>
      </joint>
      <link name='l_shoulder_link'>
        <pose frame=''>-0.01815 0.1342 1.3704 0 -0 0</pose>
        <inertial>
          <pose frame=''>0 0.02 0.015 0 -0 0</pose>
          <mass>0.242</mass>
          <inertia>
            <ixx>0.00133</ixx>
            <ixy>0</ixy>
            <ixz>0</ixz>
            <iyy>0.001</iyy>
            <iyz>0</iyz>
            <izz>0.00133</izz>
          </inertia>
        </inertial>
        <collision name='l_shoulder_link_collision'>
          <pose frame=''>0 0 0 -0.174533 -0 0</pose>
          <geometry>
            <mesh>
              <scale>1 1 1</scale>
              <uri>/home/rsdlab/catkin_ws/src/seed_r7_ros_pkg/seed_r7_description/meshes/typeF_upperbody/LARM_LINK1_mesh.dae</uri>
            </mesh>
          </geometry>
          <surface>
            <contact>
              <ode/>
            </contact>
            <friction>
              <ode>
                <mu>0.9</mu>
                <mu2>0.9</mu2>
              </ode>
              <torsional>
                <ode/>
              </torsional>
            </friction>
            <bounce/>
          </surface>
          <max_contacts>10</max_contacts>
        </collision>
        <visual name='l_shoulder_link_visual'>
          <pose frame=''>0 0 0 -0.174533 -0 0</pose>
          <geometry>
            <mesh>
              <scale>1 1 1</scale>
              <uri>/home/rsdlab/catkin_ws/src/seed_r7_ros_pkg/seed_r7_description/meshes/typeF_upperbody/LARM_LINK1_mesh.dae</uri>
            </mesh>
          </geometry>
          <material>
            <script>
              <uri>__default__</uri>
              <name>__default__</name>
            </script>
          </material>
        </visual>
        <gravity>1</gravity>
        <velocity_decay/>
        <self_collide>0</self_collide>
        <enable_wind>0</enable_wind>
        <kinematic>0</kinematic>
      </link>
      <joint name='l_shoulder_p_joint' type='revolute'>
        <child>l_shoulder_link</child>
        <parent>body_link</parent>
        <axis>
          <xyz>0 0.984808 -0.173648</xyz>
          <limit>
            <lower>-1.535</lower>
            <upper>0.261</upper>
            <effort>100</effort>
            <velocity>0.4</velocity>
          </limit>
          <dynamics>
            <damping>0.2</damping>
            <friction>0</friction>
            <spring_reference>0</spring_reference>
            <spring_stiffness>0</spring_stiffness>
          </dynamics>
          <use_parent_model_frame>1</use_parent_model_frame>
        </axis>
        <physics>
          <ode>
            <implicit_spring_damper>0</implicit_spring_damper>
            <cfm_damping>0</cfm_damping>
            <limit>
              <cfm>0</cfm>
              <erp>0.2</erp>
            </limit>
          </ode>
        </physics>
      </joint>
      <link name='l_shoulder_center'>
        <pose frame=''>-0.01815 0.19398 1.39845 0 -0 0</pose>
        <inertial>
          <pose frame=''>0 -0.01 -0.06 0 -0 0</pose>
          <mass>0.744</mass>
          <inertia>
            <ixx>0.000841</ixx>
            <ixy>0</ixy>
            <ixz>0</ixz>
            <iyy>0.000835</iyy>
            <iyz>0</iyz>
            <izz>0.000304</izz>
          </inertia>
        </inertial>
        <collision name='l_shoulder_center_collision'>
          <pose frame=''>0 0 0 0 -0 0</pose>
          <geometry>
            <mesh>
              <scale>1 1 1</scale>
              <uri>/home/rsdlab/catkin_ws/src/seed_r7_ros_pkg/seed_r7_description/meshes/typeF_upperbody/LARM_LINK2_mesh.dae</uri>
            </mesh>
          </geometry>
          <surface>
            <contact>
              <ode/>
            </contact>
            <friction>
              <ode>
                <mu>0.9</mu>
                <mu2>0.9</mu2>
              </ode>
              <torsional>
                <ode/>
              </torsional>
            </friction>
            <bounce/>
          </surface>
          <max_contacts>10</max_contacts>
        </collision>
        <visual name='l_shoulder_center_visual'>
          <pose frame=''>0 0 0 0 -0 0</pose>
          <geometry>
            <mesh>
              <scale>1 1 1</scale>
              <uri>/home/rsdlab/catkin_ws/src/seed_r7_ros_pkg/seed_r7_description/meshes/typeF_upperbody/LARM_LINK2_mesh.dae</uri>
            </mesh>
          </geometry>
          <material>
            <script>
              <uri>__default__</uri>
              <name>__default__</name>
            </script>
          </material>
        </visual>
        <gravity>1</gravity>
        <velocity_decay/>
        <self_collide>0</self_collide>
        <enable_wind>0</enable_wind>
        <kinematic>0</kinematic>
      </link>
      <joint name='l_shoulder_r_joint' type='revolute'>
        <child>l_shoulder_center</child>
        <parent>l_shoulder_link</parent>
        <axis>
          <xyz>1 0 0</xyz>
          <limit>
            <lower>0</lower>
            <upper>1.5707</upper>
            <effort>100</effort>
            <velocity>0.6</velocity>
          </limit>
          <dynamics>
            <damping>0.2</damping>
            <friction>0</friction>
            <spring_reference>0</spring_reference>
            <spring_stiffness>0</spring_stiffness>
          </dynamics>
          <use_parent_model_frame>1</use_parent_model_frame>
        </axis>
        <physics>
          <ode>
            <implicit_spring_damper>0</implicit_spring_damper>
            <cfm_damping>0</cfm_damping>
            <limit>
              <cfm>0</cfm>
              <erp>0.2</erp>
            </limit>
          </ode>
        </physics>
      </joint>
      <link name='l_upperarm_link'>
        <pose frame=''>-0.01815 0.18398 1.27145 0 -0 0</pose>
        <inertial>
          <pose frame=''>0.005 0 -0.0654 0 -0 0</pose>
          <mass>0.574</mass>
          <inertia>
            <ixx>0.00214</ixx>
            <ixy>0</ixy>
            <ixz>0</ixz>
            <iyy>0.00217</iyy>
            <iyz>0</iyz>
            <izz>0.003</izz>
          </inertia>
        </inertial>
        <collision name='l_upperarm_link_collision'>
          <pose frame=''>0 0 0 0 -0 0</pose>
          <geometry>
            <mesh>
              <scale>1 1 1</scale>
              <uri>/home/rsdlab/catkin_ws/src/seed_r7_ros_pkg/seed_r7_description/meshes/typeF_upperbody/LARM_LINK3_mesh.dae</uri>
            </mesh>
          </geometry>
          <surface>
            <contact>
              <ode/>
            </contact>
            <friction>
              <ode>
                <mu>0.9</mu>
                <mu2>0.9</mu2>
              </ode>
              <torsional>
                <ode/>
              </torsional>
            </friction>
            <bounce/>
          </surface>
          <max_contacts>10</max_contacts>
        </collision>
        <visual name='l_upperarm_link_visual'>
          <pose frame=''>0 0 0 0 -0 0</pose>
          <geometry>
            <mesh>
              <scale>1 1 1</scale>
              <uri>/home/rsdlab/catkin_ws/src/seed_r7_ros_pkg/seed_r7_description/meshes/typeF_upperbody/LARM_LINK3_mesh.dae</uri>
            </mesh>
          </geometry>
          <material>
            <script>
              <uri>__default__</uri>
              <name>__default__</name>
            </script>
          </material>
        </visual>
        <gravity>1</gravity>
        <velocity_decay/>
        <self_collide>0</self_collide>
        <enable_wind>0</enable_wind>
        <kinematic>0</kinematic>
      </link>
      <joint name='l_shoulder_y_joint' type='revolute'>
        <child>l_upperarm_link</child>
        <parent>l_shoulder_center</parent>
        <axis>
          <xyz>0 0 1</xyz>
          <limit>
            <lower>-1.5707</lower>
            <upper>0.785398</upper>
            <effort>100</effort>
            <velocity>1.2</velocity>
          </limit>
          <dynamics>
            <damping>0.2</damping>
            <friction>0</friction>
            <spring_reference>0</spring_reference>
            <spring_stiffness>0</spring_stiffness>
          </dynamics>
          <use_parent_model_frame>1</use_parent_model_frame>
        </axis>
        <physics>
          <ode>
            <implicit_spring_damper>0</implicit_spring_damper>
            <cfm_damping>0</cfm_damping>
            <limit>
              <cfm>0</cfm>
              <erp>0.2</erp>
            </limit>
          </ode>
        </physics>
      </joint>
      <link name='l_elbow_link'>
        <pose frame=''>0.01685 0.18398 1.10895 0 -0 0</pose>
        <inertial>
          <pose frame=''>-0.03 0 -0.0546 0 -0 0</pose>
          <mass>0.711</mass>
          <inertia>
            <ixx>0.00178</ixx>
            <ixy>0</ixy>
            <ixz>0</ixz>
            <iyy>0.00179</iyy>
            <iyz>0</iyz>
            <izz>0.0035</izz>
          </inertia>
        </inertial>
        <collision name='l_elbow_link_collision'>
          <pose frame=''>-0.035 0 -0.035 0 -0 0</pose>
          <geometry>
            <mesh>
              <scale>1 1 1</scale>
              <uri>/home/rsdlab/catkin_ws/src/seed_r7_ros_pkg/seed_r7_description/meshes/typeF_upperbody/LARM_LINK4_mesh.dae</uri>
            </mesh>
          </geometry>
          <surface>
            <contact>
              <ode/>
            </contact>
            <friction>
              <ode>
                <mu>0.9</mu>
                <mu2>0.9</mu2>
              </ode>
              <torsional>
                <ode/>
              </torsional>
            </friction>
            <bounce/>
          </surface>
          <max_contacts>10</max_contacts>
        </collision>
        <visual name='l_elbow_link_visual'>
          <pose frame=''>-0.035 0 -0.035 0 -0 0</pose>
          <geometry>
            <mesh>
              <scale>1 1 1</scale>
              <uri>/home/rsdlab/catkin_ws/src/seed_r7_ros_pkg/seed_r7_description/meshes/typeF_upperbody/LARM_LINK4_mesh.dae</uri>
            </mesh>
          </geometry>
          <material>
            <script>
              <uri>__default__</uri>
              <name>__default__</name>
            </script>
          </material>
        </visual>
        <gravity>1</gravity>
        <velocity_decay/>
        <self_collide>0</self_collide>
        <enable_wind>0</enable_wind>
        <kinematic>0</kinematic>
      </link>
      <joint name='l_elbow_joint' type='revolute'>
        <child>l_elbow_link</child>
        <parent>l_upperarm_link</parent>
        <axis>
          <xyz>0 1 0</xyz>
          <limit>
            <lower>-3</lower>
            <upper>0</upper>
            <effort>100</effort>
            <velocity>1.2</velocity>
          </limit>
          <dynamics>
            <damping>0.2</damping>
            <friction>0</friction>
            <spring_reference>0</spring_reference>
            <spring_stiffness>0</spring_stiffness>
          </dynamics>
          <use_parent_model_frame>1</use_parent_model_frame>
        </axis>
        <physics>
          <ode>
            <implicit_spring_damper>0</implicit_spring_damper>
            <cfm_damping>0</cfm_damping>
            <limit>
              <cfm>0</cfm>
              <erp>0.2</erp>
            </limit>
          </ode>
        </physics>
      </joint>
      <link name='l_forearm_link'>
        <pose frame=''>-0.01815 0.18398 1.03895 0 -0 0</pose>
        <inertial>
          <pose frame=''>0.006 0 -0.0738 0 -0 0</pose>
          <mass>0.132</mass>
          <inertia>
            <ixx>0.0007</ixx>
            <ixy>0</ixy>
            <ixz>0</ixz>
            <iyy>0.0007</iyy>
            <iyz>0</iyz>
            <izz>0.0004</izz>
          </inertia>
        </inertial>
        <collision name='l_forearm_link_collision'>
          <pose frame=''>0 0 0 0 0 -1.5708</pose>
          <geometry>
            <mesh>
              <scale>1 1 1</scale>
              <uri>/home/rsdlab/catkin_ws/src/seed_r7_ros_pkg/seed_r7_description/meshes/typeF_upperbody/LARM_LINK5_mesh.dae</uri>
            </mesh>
          </geometry>
          <surface>
            <contact>
              <ode/>
            </contact>
            <friction>
              <ode>
                <mu>0.9</mu>
                <mu2>0.9</mu2>
              </ode>
              <torsional>
                <ode/>
              </torsional>
            </friction>
            <bounce/>
          </surface>
          <max_contacts>10</max_contacts>
        </collision>
        <visual name='l_forearm_link_visual'>
          <pose frame=''>0 0 0 0 0 -1.5708</pose>
          <geometry>
            <mesh>
              <scale>1 1 1</scale>
              <uri>/home/rsdlab/catkin_ws/src/seed_r7_ros_pkg/seed_r7_description/meshes/typeF_upperbody/LARM_LINK5_mesh.dae</uri>
            </mesh>
          </geometry>
          <material>
            <script>
              <uri>__default__</uri>
              <name>__default__</name>
            </script>
          </material>
        </visual>
        <gravity>1</gravity>
        <velocity_decay/>
        <self_collide>0</self_collide>
        <enable_wind>0</enable_wind>
        <kinematic>0</kinematic>
      </link>
      <joint name='l_wrist_y_joint' type='revolute'>
        <child>l_forearm_link</child>
        <parent>l_elbow_link</parent>
        <axis>
          <xyz>0 0 1</xyz>
          <limit>
            <lower>-1.5707</lower>
            <upper>1.5707</upper>
            <effort>100</effort>
            <velocity>1.3</velocity>
          </limit>
          <dynamics>
            <damping>0.2</damping>
            <friction>0</friction>
            <spring_reference>0</spring_reference>
            <spring_stiffness>0</spring_stiffness>
          </dynamics>
          <use_parent_model_frame>1</use_parent_model_frame>
        </axis>
        <physics>
          <ode>
            <implicit_spring_damper>0</implicit_spring_damper>
            <cfm_damping>0</cfm_damping>
            <limit>
              <cfm>0</cfm>
              <erp>0.2</erp>
            </limit>
          </ode>
        </physics>
      </joint>
      <link name='l_wrist_center'>
        <pose frame=''>-0.01815 0.18398 0.843446 0 -0 0</pose>
        <inertial>
          <pose frame=''>0 0 0 0 -0 0</pose>
          <mass>0.05</mass>
          <inertia>
            <ixx>0.0001</ixx>
            <ixy>0</ixy>
            <ixz>0</ixz>
            <iyy>0.0001</iyy>
            <iyz>0</iyz>
            <izz>0.0001</izz>
          </inertia>
        </inertial>
        <gravity>1</gravity>
        <velocity_decay/>
        <self_collide>0</self_collide>
        <enable_wind>0</enable_wind>
        <kinematic>0</kinematic>
      </link>
      <joint name='l_wrist_p_joint' type='revolute'>
        <child>l_wrist_center</child>
        <parent>l_forearm_link</parent>
        <axis>
          <xyz>0 1 0</xyz>
          <limit>
            <lower>-0.087</lower>
            <upper>0.087</upper>
            <effort>100</effort>
            <velocity>0.9</velocity>
          </limit>
          <dynamics>
            <damping>0.2</damping>
            <friction>0</friction>
            <spring_reference>0</spring_reference>
            <spring_stiffness>0</spring_stiffness>
          </dynamics>
          <use_parent_model_frame>1</use_parent_model_frame>
        </axis>
        <physics>
          <ode>
            <implicit_spring_damper>0</implicit_spring_damper>
            <cfm_damping>0</cfm_damping>
            <limit>
              <cfm>0</cfm>
              <erp>0.2</erp>
            </limit>
          </ode>
        </physics>
      </joint>
      <link name='l_hand_link'>
        <pose frame=''>-0.01815 0.18398 0.843446 0 -0 0</pose>
        <inertial>
          <pose frame=''>0 0 -0.0875 0 -0 0</pose>
          <mass>0.183</mass>
          <inertia>
            <ixx>0.000601</ixx>
            <ixy>0</ixy>
            <ixz>0</ixz>
            <iyy>0.00055</iyy>
            <iyz>0</iyz>
            <izz>0.000102</izz>
          </inertia>
        </inertial>
        <collision name='l_hand_link_collision'>
          <pose frame=''>0 0 -0.093 -0.7 0 0</pose>
          <geometry>
            <box>
              <size>0.036 0.07 0.03</size>
            </box>
          </geometry>
          <surface>
            <contact>
              <ode/>
            </contact>
            <friction>
              <ode>
                <mu>0.9</mu>
                <mu2>0.9</mu2>
              </ode>
              <torsional>
                <ode/>
              </torsional>
            </friction>
            <bounce/>
          </surface>
          <max_contacts>10</max_contacts>
        </collision>
        <collision name='l_hand_link_collision_1'>
          <pose frame=''>0 0.007 -0.055 0.1 -0 0</pose>
          <geometry>
            <box>
              <size>0.036 0.05 0.07</size>
            </box>
          </geometry>
          <surface>
            <contact>
              <ode/>
            </contact>
            <friction>
              <ode>
                <mu>0.9</mu>
                <mu2>0.9</mu2>
              </ode>
              <torsional>
                <ode/>
              </torsional>
            </friction>
            <bounce/>
          </surface>
          <max_contacts>10</max_contacts>
        </collision>
        <visual name='l_hand_link_visual'>
          <pose frame=''>0 0 0 0 -0 -3.14159</pose>
          <geometry>
            <mesh>
              <scale>1 1 1</scale>
              <uri>/home/rsdlab/catkin_ws/src/seed_r7_ros_pkg/seed_r7_description/meshes/trx_s/RARM_LINK7_mesh.dae</uri>
            </mesh>
          </geometry>
          <material>
            <script>
              <uri>__default__</uri>
              <name>__default__</name>
            </script>
          </material>
        </visual>
        <gravity>1</gravity>
        <velocity_decay/>
        <self_collide>0</self_collide>
        <enable_wind>0</enable_wind>
        <kinematic>0</kinematic>
      </link>
      <joint name='l_wrist_r_joint' type='revolute'>
        <child>l_hand_link</child>
        <parent>l_wrist_center</parent>
        <axis>
          <xyz>1 0 0</xyz>
          <limit>
            <lower>-1.484</lower>
            <upper>0.436</upper>
            <effort>100</effort>
            <velocity>2.1</velocity>
          </limit>
          <dynamics>
            <damping>0.2</damping>
            <friction>0</friction>
            <spring_reference>0</spring_reference>
            <spring_stiffness>0</spring_stiffness>
          </dynamics>
          <use_parent_model_frame>1</use_parent_model_frame>
        </axis>
        <physics>
          <ode>
            <implicit_spring_damper>0</implicit_spring_damper>
            <cfm_damping>0</cfm_damping>
            <limit>
              <cfm>0</cfm>
              <erp>0.2</erp>
            </limit>
          </ode>
        </physics>
      </joint>
      <link name='l_indexbase_link'>
        <pose frame=''>-0.01815 0.19698 0.728446 0 -0 0</pose>
        <inertial>
          <pose frame=''>0 -0.042408 -0.037196 0 -0 0</pose>
          <mass>0.3</mass>
          <inertia>
            <ixx>0.00230024</ixx>
            <ixy>0</ixy>
            <ixz>0</ixz>
            <iyy>0.00034078</iyy>
            <iyz>-7.64367e-05</iyz>
            <izz>0.000459461</izz>
          </inertia>
        </inertial>
        <collision name='l_indexbase_link_collision'>
          <pose frame=''>0 -0.013494 -0.021422 0.85 -0 0</pose>
          <geometry>
            <box>
              <size>0.041 0.061 0.016</size>
            </box>
          </geometry>
          <surface>
            <contact>
              <ode/>
            </contact>
            <friction>
              <ode>
                <mu>0.9</mu>
                <mu2>0.9</mu2>
              </ode>
              <torsional>
                <ode/>
              </torsional>
            </friction>
            <bounce/>
          </surface>
          <max_contacts>10</max_contacts>
        </collision>
        <collision name='l_indexbase_link_fixed_joint_lump__l_indexmid_link_collision_1'>
          <pose frame=''>0 -0.042754 -0.042615 0.3 -0 0</pose>
          <geometry>
            <box>
              <size>0.034 0.03 0.016</size>
            </box>
          </geometry>
          <surface>
            <contact>
              <ode/>
            </contact>
            <friction>
              <ode>
                <mu>0.9</mu>
                <mu2>0.9</mu2>
              </ode>
              <torsional>
                <ode/>
              </torsional>
            </friction>
            <bounce/>
          </surface>
          <max_contacts>10</max_contacts>
        </collision>
        <collision name='l_indexbase_link_fixed_joint_lump__l_indexend_link_collision_2'>
          <pose frame=''>0 -0.06347 -0.043972 0 -0 0</pose>
          <geometry>
            <box>
              <size>0.04 0.028 0.016</size>
            </box>
          </geometry>
          <surface>
            <contact>
              <ode/>
            </contact>
            <friction>
              <ode>
                <mu>0.9</mu>
                <mu2>0.9</mu2>
              </ode>
              <torsional>
                <ode/>
              </torsional>
            </friction>
            <bounce/>
          </surface>
          <max_contacts>10</max_contacts>
        </collision>
        <visual name='l_indexbase_link_visual'>
          <pose frame=''>0 -0.013 0.115 0 -0 -3.14159</pose>
          <geometry>
            <mesh>
              <scale>1 1 1</scale>
              <uri>/home/rsdlab/catkin_ws/src/seed_r7_ros_pkg/seed_r7_description/meshes/trx_s/RARM_INDEX_LINK1_mesh.dae</uri>
            </mesh>
          </geometry>
          <material>
            <script>
              <uri>__default__</uri>
              <name>__default__</name>
            </script>
          </material>
        </visual>
        <visual name='l_indexbase_link_fixed_joint_lump__l_indexmid_link_visual_1'>
          <pose frame=''>0 -0.013 0.115 0 -0 -3.14159</pose>
          <geometry>
            <mesh>
              <scale>1 1 1</scale>
              <uri>/home/rsdlab/catkin_ws/src/seed_r7_ros_pkg/seed_r7_description/meshes/trx_s/RARM_INDEX_LINK2_mesh.dae</uri>
            </mesh>
          </geometry>
          <material>
            <script>
              <uri>__default__</uri>
              <name>__default__</name>
            </script>
          </material>
        </visual>
        <visual name='l_indexbase_link_fixed_joint_lump__l_indexend_link_visual_2'>
          <pose frame=''>0 -0.013 0.115 0 -0 -3.14159</pose>
          <geometry>
            <mesh>
              <scale>1 1 1</scale>
              <uri>/home/rsdlab/catkin_ws/src/seed_r7_ros_pkg/seed_r7_description/meshes/trx_s/RARM_INDEX_LINK3_mesh.dae</uri>
            </mesh>
          </geometry>
          <material>
            <script>
              <uri>__default__</uri>
              <name>__default__</name>
            </script>
          </material>
        </visual>
        <velocity_decay/>
        <velocity_decay/>
        <gravity>1</gravity>
        <velocity_decay/>
        <self_collide>0</self_collide>
        <enable_wind>0</enable_wind>
        <kinematic>0</kinematic>
      </link>
      <joint name='l_indexbase_joint' type='revolute'>
        <child>l_indexbase_link</child>
        <parent>l_hand_link</parent>
        <axis>
          <xyz>1 0 0</xyz>
          <limit>
            <lower>-1e+16</lower>
            <upper>1e+16</upper>
          </limit>
          <dynamics>
            <spring_reference>0</spring_reference>
            <spring_stiffness>0</spring_stiffness>
          </dynamics>
          <use_parent_model_frame>1</use_parent_model_frame>
        </axis>
      </joint>
      <link name='l_thumb_link'>
        <pose frame=''>-0.01815 0.161625 0.763801 0 -0 0</pose>
        <inertial>
          <pose frame=''>0 -0.05 -0.06 0 -0 0</pose>
          <mass>0.1</mass>
          <inertia>
            <ixx>0.001</ixx>
            <ixy>0</ixy>
            <ixz>0</ixz>
            <iyy>0.0001</iyy>
            <iyz>0</iyz>
            <izz>0.0001</izz>
          </inertia>
        </inertial>
        <collision name='l_thumb_link_collision'>
          <pose frame=''>0 -0.019645 -0.010355 -0.63 0 0</pose>
          <geometry>
            <box>
              <size>0.012 0.008 0.05</size>
            </box>
          </geometry>
          <surface>
            <contact>
              <ode/>
            </contact>
            <friction>
              <ode>
                <mu>0.9</mu>
                <mu2>0.9</mu2>
              </ode>
              <torsional>
                <ode/>
              </torsional>
            </friction>
            <bounce/>
          </surface>
          <max_contacts>10</max_contacts>
        </collision>
        <collision name='l_thumb_link_collision_1'>
          <pose frame=''>0 -0.035645 -0.050355 -0.1 0 0</pose>
          <geometry>
            <box>
              <size>0.012 0.008 0.05</size>
            </box>
          </geometry>
          <surface>
            <contact>
              <ode/>
            </contact>
            <friction>
              <ode>
                <mu>0.9</mu>
                <mu2>0.9</mu2>
              </ode>
              <torsional>
                <ode/>
              </torsional>
            </friction>
            <bounce/>
          </surface>
          <max_contacts>10</max_contacts>
        </collision>
        <visual name='l_thumb_link_visual'>
          <pose frame=''>0 0.022355 0.079645 0 -0 -3.14159</pose>
          <geometry>
            <mesh>
              <scale>1 1 1</scale>
              <uri>/home/rsdlab/catkin_ws/src/seed_r7_ros_pkg/seed_r7_description/meshes/trx_s/RARM_THUMB_LINK_mesh.dae</uri>
            </mesh>
          </geometry>
          <material>
            <script>
              <uri>__default__</uri>
              <name>__default__</name>
            </script>
          </material>
        </visual>
        <gravity>1</gravity>
        <velocity_decay/>
        <self_collide>0</self_collide>
        <enable_wind>0</enable_wind>
        <kinematic>0</kinematic>
      </link>
      <joint name='l_thumb_joint' type='revolute'>
        <child>l_thumb_link</child>
        <parent>l_hand_link</parent>
        <axis>
          <xyz>1 0 0</xyz>
          <limit>
            <lower>-1</lower>
            <upper>1</upper>
            <effort>50</effort>
            <velocity>0.5</velocity>
          </limit>
          <dynamics>
            <damping>0.2</damping>
            <friction>0</friction>
            <spring_reference>0</spring_reference>
            <spring_stiffness>0</spring_stiffness>
          </dynamics>
          <use_parent_model_frame>1</use_parent_model_frame>
        </axis>
        <physics>
          <ode>
            <implicit_spring_damper>0</implicit_spring_damper>
            <cfm_damping>0</cfm_damping>
            <limit>
              <cfm>0</cfm>
              <erp>0.2</erp>
            </limit>
          </ode>
        </physics>
      </joint>
      <link name='neck_link'>
        <pose frame=''>0 0 1.419 0 -0 0</pose>
        <inertial>
          <pose frame=''>0 0 0.0595 0 -0 0</pose>
          <mass>0.341</mass>
          <inertia>
            <ixx>0.001</ixx>
            <ixy>0</ixy>
            <ixz>0</ixz>
            <iyy>0.001</iyy>
            <iyz>0</iyz>
            <izz>0.002</izz>
          </inertia>
        </inertial>
        <collision name='neck_link_collision'>
          <pose frame=''>0 0 0 0 -0 0</pose>
          <geometry>
            <mesh>
              <scale>1 1 1</scale>
              <uri>/home/rsdlab/catkin_ws/src/seed_r7_ros_pkg/seed_r7_description/meshes/typeF_upperbody/NECK_LINK1_mesh.dae</uri>
            </mesh>
          </geometry>
          <surface>
            <contact>
              <ode/>
            </contact>
            <friction>
              <ode>
                <mu>0.9</mu>
                <mu2>0.9</mu2>
              </ode>
              <torsional>
                <ode/>
              </torsional>
            </friction>
            <bounce/>
          </surface>
          <max_contacts>10</max_contacts>
        </collision>
        <visual name='neck_link_visual'>
          <pose frame=''>0 0 0 0 -0 0</pose>
          <geometry>
            <mesh>
              <scale>1 1 1</scale>
              <uri>/home/rsdlab/catkin_ws/src/seed_r7_ros_pkg/seed_r7_description/meshes/typeF_upperbody/NECK_LINK1_mesh.dae</uri>
            </mesh>
          </geometry>
          <material>
            <script>
              <uri>__default__</uri>
              <name>__default__</name>
            </script>
          </material>
        </visual>
        <gravity>1</gravity>
        <velocity_decay/>
        <self_collide>0</self_collide>
        <enable_wind>0</enable_wind>
        <kinematic>0</kinematic>
      </link>
      <joint name='neck_y_joint' type='revolute'>
        <child>neck_link</child>
        <parent>body_link</parent>
        <axis>
          <xyz>0 0 1</xyz>
          <limit>
            <lower>-2.09</lower>
            <upper>2.09</upper>
            <effort>100</effort>
            <velocity>1.6</velocity>
          </limit>
          <dynamics>
            <damping>0.2</damping>
            <friction>0</friction>
            <spring_reference>0</spring_reference>
            <spring_stiffness>0</spring_stiffness>
          </dynamics>
          <use_parent_model_frame>1</use_parent_model_frame>
        </axis>
        <physics>
          <ode>
            <implicit_spring_damper>0</implicit_spring_damper>
            <cfm_damping>0</cfm_damping>
            <limit>
              <cfm>0</cfm>
              <erp>0.2</erp>
            </limit>
          </ode>
        </physics>
      </joint>
      <link name='head_base_link'>
        <pose frame=''>0 0 1.5235 0 -0 0</pose>
        <inertial>
          <pose frame=''>0 0 0 0 -0 0</pose>
          <mass>0.1</mass>
          <inertia>
            <ixx>0.0005</ixx>
            <ixy>0</ixy>
            <ixz>0</ixz>
            <iyy>0.0005</iyy>
            <iyz>0</iyz>
            <izz>0.0005</izz>
          </inertia>
        </inertial>
        <collision name='head_base_link_collision'>
          <pose frame=''>0 0 0 0 -0 0</pose>
          <geometry>
            <mesh>
              <scale>1 1 1</scale>
              <uri>/home/rsdlab/catkin_ws/src/seed_r7_ros_pkg/seed_r7_description/meshes/typeF_upperbody/NECK_LINK2_mesh.dae</uri>
            </mesh>
          </geometry>
          <surface>
            <contact>
              <ode/>
            </contact>
            <friction>
              <ode>
                <mu>0.9</mu>
                <mu2>0.9</mu2>
              </ode>
              <torsional>
                <ode/>
              </torsional>
            </friction>
            <bounce/>
          </surface>
          <max_contacts>10</max_contacts>
        </collision>
        <visual name='head_base_link_visual'>
          <pose frame=''>0 0 0 0 -0 0</pose>
          <geometry>
            <mesh>
              <scale>1 1 1</scale>
              <uri>/home/rsdlab/catkin_ws/src/seed_r7_ros_pkg/seed_r7_description/meshes/typeF_upperbody/NECK_LINK2_mesh.dae</uri>
            </mesh>
          </geometry>
          <material>
            <script>
              <uri>__default__</uri>
              <name>__default__</name>
            </script>
          </material>
        </visual>
        <gravity>1</gravity>
        <velocity_decay/>
        <self_collide>0</self_collide>
        <enable_wind>0</enable_wind>
        <kinematic>0</kinematic>
      </link>
      <joint name='neck_p_joint' type='revolute'>
        <child>head_base_link</child>
        <parent>neck_link</parent>
        <axis>
          <xyz>0 1 0</xyz>
          <limit>
            <lower>-0.262</lower>
            <upper>0.96</upper>
            <effort>100</effort>
            <velocity>2.1</velocity>
          </limit>
          <dynamics>
            <damping>0.2</damping>
            <friction>0</friction>
            <spring_reference>0</spring_reference>
            <spring_stiffness>0</spring_stiffness>
          </dynamics>
          <use_parent_model_frame>1</use_parent_model_frame>
        </axis>
        <physics>
          <ode>
            <implicit_spring_damper>0</implicit_spring_damper>
            <cfm_damping>0</cfm_damping>
            <limit>
              <cfm>0</cfm>
              <erp>0.2</erp>
            </limit>
          </ode>
        </physics>
      </joint>
      <link name='head_link'>
        <pose frame=''>0 0 1.5235 0 -0 0</pose>
        <inertial>
          <pose frame=''>0.01 0 0.07 0 -0 0</pose>
          <mass>0.974</mass>
          <inertia>
            <ixx>0.005</ixx>
            <ixy>0</ixy>
            <ixz>0</ixz>
            <iyy>0.005</iyy>
            <iyz>0</iyz>
            <izz>0.005</izz>
          </inertia>
        </inertial>
        <collision name='head_link_collision'>
          <pose frame=''>0 0 0 0 -0 0</pose>
          <geometry>
            <mesh>
              <scale>1 1 1</scale>
              <uri>/home/rsdlab/catkin_ws/src/seed_r7_ros_pkg/seed_r7_description/meshes/typeF_upperbody/NECK_LINK3_mesh.dae</uri>
            </mesh>
          </geometry>
          <surface>
            <contact>
              <ode/>
            </contact>
            <friction>
              <ode>
                <mu>0.9</mu>
                <mu2>0.9</mu2>
              </ode>
              <torsional>
                <ode/>
              </torsional>
            </friction>
            <bounce/>
          </surface>
          <max_contacts>10</max_contacts>
        </collision>
        <visual name='head_link_visual'>
          <pose frame=''>0 0 0 0 -0 0</pose>
          <geometry>
            <mesh>
              <scale>1 1 1</scale>
              <uri>/home/rsdlab/catkin_ws/src/seed_r7_ros_pkg/seed_r7_description/meshes/typeF_upperbody/NECK_LINK3_mesh.dae</uri>
            </mesh>
          </geometry>
          <material>
            <script>
              <uri>__default__</uri>
              <name>__default__</name>
            </script>
          </material>
        </visual>
        <velocity_decay/>
        <gravity>1</gravity>
        <velocity_decay/>
        <sensor name='camera1' type='camera'>
          <update_rate>15</update_rate>
          <camera name='head'>
            <horizontal_fov>1.7</horizontal_fov>
            <image>
              <width>800</width>
              <height>800</height>
              <format>R8G8B8</format>
            </image>
            <clip>
              <near>0.15</near>
              <far>300</far>
            </clip>
            <noise>
              <type>gaussian</type>
              <mean>0</mean>
              <stddev>0.007</stddev>
            </noise>
          </camera>
          <plugin name='camera_controller' filename='libgazebo_ros_camera.so'>
            <alwaysOn>1</alwaysOn>
            <updateRate>0.0</updateRate>
            <cameraName>camera</cameraName>
            <imageTopicName>image_raw</imageTopicName>
            <cameraInfoTopicName>camera_info</cameraInfoTopicName>
            <frameName>camera_optical_frame</frameName>
            <hackBaseline>0.0</hackBaseline>
            <distortionK1>0.0</distortionK1>
            <distortionK2>0.0</distortionK2>
            <distortionK3>0.0</distortionK3>
            <distortionT1>0.0</distortionT1>
            <distortionT2>0.0</distortionT2>
            <CxPrime>0</CxPrime>
            <Cx>0.0</Cx>
            <Cy>0.0</Cy>
            <focalLength>0.0</focalLength>
            <robotNamespace>/</robotNamespace>
          </plugin>
          <pose frame=''>0.1 0.035 0.09 0 0.15 0</pose>
        </sensor>
        <self_collide>0</self_collide>
        <enable_wind>0</enable_wind>
        <kinematic>0</kinematic>
      </link>
      <joint name='neck_r_joint' type='revolute'>
        <child>head_link</child>
        <parent>head_base_link</parent>
        <axis>
          <xyz>1 0 0</xyz>
          <limit>
            <lower>-0.087</lower>
            <upper>0.087</upper>
            <effort>100</effort>
            <velocity>0.9</velocity>
          </limit>
          <dynamics>
            <damping>0.2</damping>
            <friction>0</friction>
            <spring_reference>0</spring_reference>
            <spring_stiffness>0</spring_stiffness>
          </dynamics>
          <use_parent_model_frame>1</use_parent_model_frame>
        </axis>
        <physics>
          <ode>
            <implicit_spring_damper>0</implicit_spring_damper>
            <cfm_damping>0</cfm_damping>
            <limit>
              <cfm>0</cfm>
              <erp>0.2</erp>
            </limit>
          </ode>
        </physics>
      </joint>
      <link name='r_shoulder_link'>
        <pose frame=''>-0.01815 -0.1342 1.3704 0 -0 0</pose>
        <inertial>
          <pose frame=''>0 -0.02 0.015 0 -0 0</pose>
          <mass>0.242</mass>
          <inertia>
            <ixx>0.00133</ixx>
            <ixy>0</ixy>
            <ixz>0</ixz>
            <iyy>0.001</iyy>
            <iyz>0</iyz>
            <izz>0.00133</izz>
          </inertia>
        </inertial>
        <collision name='r_shoulder_link_collision'>
          <pose frame=''>0 0 0 0.174533 -0 0</pose>
          <geometry>
            <mesh>
              <scale>1 1 1</scale>
              <uri>/home/rsdlab/catkin_ws/src/seed_r7_ros_pkg/seed_r7_description/meshes/typeF_upperbody/RARM_LINK1_mesh.dae</uri>
            </mesh>
          </geometry>
          <surface>
            <contact>
              <ode/>
            </contact>
            <friction>
              <ode>
                <mu>0.9</mu>
                <mu2>0.9</mu2>
              </ode>
              <torsional>
                <ode/>
              </torsional>
            </friction>
            <bounce/>
          </surface>
          <max_contacts>10</max_contacts>
        </collision>
        <visual name='r_shoulder_link_visual'>
          <pose frame=''>0 0 0 0.174533 -0 0</pose>
          <geometry>
            <mesh>
              <scale>1 1 1</scale>
              <uri>/home/rsdlab/catkin_ws/src/seed_r7_ros_pkg/seed_r7_description/meshes/typeF_upperbody/RARM_LINK1_mesh.dae</uri>
            </mesh>
          </geometry>
          <material>
            <script>
              <uri>__default__</uri>
              <name>__default__</name>
            </script>
          </material>
        </visual>
        <gravity>1</gravity>
        <velocity_decay/>
        <self_collide>0</self_collide>
        <enable_wind>0</enable_wind>
        <kinematic>0</kinematic>
      </link>
      <joint name='r_shoulder_p_joint' type='revolute'>
        <child>r_shoulder_link</child>
        <parent>body_link</parent>
        <axis>
          <xyz>0 0.984808 0.173648</xyz>
          <limit>
            <lower>-1.535</lower>
            <upper>0.261</upper>
            <effort>100</effort>
            <velocity>0.4</velocity>
          </limit>
          <dynamics>
            <damping>0.2</damping>
            <friction>0</friction>
            <spring_reference>0</spring_reference>
            <spring_stiffness>0</spring_stiffness>
          </dynamics>
          <use_parent_model_frame>1</use_parent_model_frame>
        </axis>
        <physics>
          <ode>
            <implicit_spring_damper>0</implicit_spring_damper>
            <cfm_damping>0</cfm_damping>
            <limit>
              <cfm>0</cfm>
              <erp>0.2</erp>
            </limit>
          </ode>
        </physics>
      </joint>
      <link name='r_shoulder_center'>
        <pose frame=''>-0.01815 -0.193978 1.39845 0 -0 0</pose>
        <inertial>
          <pose frame=''>0 0.01 -0.06 0 -0 0</pose>
          <mass>0.744</mass>
          <inertia>
            <ixx>0.000841</ixx>
            <ixy>0</ixy>
            <ixz>0</ixz>
            <iyy>0.000835</iyy>
            <iyz>0</iyz>
            <izz>0.000305</izz>
          </inertia>
        </inertial>
        <collision name='r_shoulder_center_collision'>
          <pose frame=''>0 0 0 0 -0 0</pose>
          <geometry>
            <mesh>
              <scale>1 1 1</scale>
              <uri>/home/rsdlab/catkin_ws/src/seed_r7_ros_pkg/seed_r7_description/meshes/typeF_upperbody/RARM_LINK2_mesh.dae</uri>
            </mesh>
          </geometry>
          <surface>
            <contact>
              <ode/>
            </contact>
            <friction>
              <ode>
                <mu>0.9</mu>
                <mu2>0.9</mu2>
              </ode>
              <torsional>
                <ode/>
              </torsional>
            </friction>
            <bounce/>
          </surface>
          <max_contacts>10</max_contacts>
        </collision>
        <visual name='r_shoulder_center_visual'>
          <pose frame=''>0 0 0 0 -0 0</pose>
          <geometry>
            <mesh>
              <scale>1 1 1</scale>
              <uri>/home/rsdlab/catkin_ws/src/seed_r7_ros_pkg/seed_r7_description/meshes/typeF_upperbody/RARM_LINK2_mesh.dae</uri>
            </mesh>
          </geometry>
          <material>
            <script>
              <uri>__default__</uri>
              <name>__default__</name>
            </script>
          </material>
        </visual>
        <gravity>1</gravity>
        <velocity_decay/>
        <self_collide>0</self_collide>
        <enable_wind>0</enable_wind>
        <kinematic>0</kinematic>
      </link>
      <joint name='r_shoulder_r_joint' type='revolute'>
        <child>r_shoulder_center</child>
        <parent>r_shoulder_link</parent>
        <axis>
          <xyz>1 0 0</xyz>
          <limit>
            <lower>-1.5707</lower>
            <upper>0</upper>
            <effort>100</effort>
            <velocity>0.6</velocity>
          </limit>
          <dynamics>
            <damping>0.2</damping>
            <friction>0</friction>
            <spring_reference>0</spring_reference>
            <spring_stiffness>0</spring_stiffness>
          </dynamics>
          <use_parent_model_frame>1</use_parent_model_frame>
        </axis>
        <physics>
          <ode>
            <implicit_spring_damper>0</implicit_spring_damper>
            <cfm_damping>0</cfm_damping>
            <limit>
              <cfm>0</cfm>
              <erp>0.2</erp>
            </limit>
          </ode>
        </physics>
      </joint>
      <link name='r_upperarm_link'>
        <pose frame=''>-0.01815 -0.183978 1.27145 0 -0 0</pose>
        <inertial>
          <pose frame=''>0.005 0 -0.0654 0 -0 0</pose>
          <mass>0.574</mass>
          <inertia>
            <ixx>0.00214</ixx>
            <ixy>0</ixy>
            <ixz>0</ixz>
            <iyy>0.00217</iyy>
            <iyz>0</iyz>
            <izz>0.003</izz>
          </inertia>
        </inertial>
        <collision name='r_upperarm_link_collision'>
          <pose frame=''>0 0 0 0 -0 0</pose>
          <geometry>
            <mesh>
              <scale>1 1 1</scale>
              <uri>/home/rsdlab/catkin_ws/src/seed_r7_ros_pkg/seed_r7_description/meshes/typeF_upperbody/RARM_LINK3_mesh.dae</uri>
            </mesh>
          </geometry>
          <surface>
            <contact>
              <ode/>
            </contact>
            <friction>
              <ode>
                <mu>0.9</mu>
                <mu2>0.9</mu2>
              </ode>
              <torsional>
                <ode/>
              </torsional>
            </friction>
            <bounce/>
          </surface>
          <max_contacts>10</max_contacts>
        </collision>
        <visual name='r_upperarm_link_visual'>
          <pose frame=''>0 0 0 0 -0 0</pose>
          <geometry>
            <mesh>
              <scale>1 1 1</scale>
              <uri>/home/rsdlab/catkin_ws/src/seed_r7_ros_pkg/seed_r7_description/meshes/typeF_upperbody/RARM_LINK3_mesh.dae</uri>
            </mesh>
          </geometry>
          <material>
            <script>
              <uri>__default__</uri>
              <name>__default__</name>
            </script>
          </material>
        </visual>
        <gravity>1</gravity>
        <velocity_decay/>
        <self_collide>0</self_collide>
        <enable_wind>0</enable_wind>
        <kinematic>0</kinematic>
      </link>
      <joint name='r_shoulder_y_joint' type='revolute'>
        <child>r_upperarm_link</child>
        <parent>r_shoulder_center</parent>
        <axis>
          <xyz>0 0 1</xyz>
          <limit>
            <lower>-0.785398</lower>
            <upper>1.5707</upper>
            <effort>100</effort>
            <velocity>1.2</velocity>
          </limit>
          <dynamics>
            <damping>0.2</damping>
            <friction>0</friction>
            <spring_reference>0</spring_reference>
            <spring_stiffness>0</spring_stiffness>
          </dynamics>
          <use_parent_model_frame>1</use_parent_model_frame>
        </axis>
        <physics>
          <ode>
            <implicit_spring_damper>0</implicit_spring_damper>
            <cfm_damping>0</cfm_damping>
            <limit>
              <cfm>0</cfm>
              <erp>0.2</erp>
            </limit>
          </ode>
        </physics>
      </joint>
      <link name='r_elbow_link'>
        <pose frame=''>0.01685 -0.183978 1.10895 0 -0 0</pose>
        <inertial>
          <pose frame=''>-0.03 0 -0.0546 0 -0 0</pose>
          <mass>0.711</mass>
          <inertia>
            <ixx>0.00178</ixx>
            <ixy>0</ixy>
            <ixz>0</ixz>
            <iyy>0.00179</iyy>
            <iyz>0</iyz>
            <izz>0.0035</izz>
          </inertia>
        </inertial>
        <collision name='r_elbow_link_collision'>
          <pose frame=''>-0.035 0 -0.035 0 -0 0</pose>
          <geometry>
            <mesh>
              <scale>1 1 1</scale>
              <uri>/home/rsdlab/catkin_ws/src/seed_r7_ros_pkg/seed_r7_description/meshes/typeF_upperbody/RARM_LINK4_mesh.dae</uri>
            </mesh>
          </geometry>
          <surface>
            <contact>
              <ode/>
            </contact>
            <friction>
              <ode>
                <mu>0.9</mu>
                <mu2>0.9</mu2>
              </ode>
              <torsional>
                <ode/>
              </torsional>
            </friction>
            <bounce/>
          </surface>
          <max_contacts>10</max_contacts>
        </collision>
        <visual name='r_elbow_link_visual'>
          <pose frame=''>-0.035 0 -0.035 0 -0 0</pose>
          <geometry>
            <mesh>
              <scale>1 1 1</scale>
              <uri>/home/rsdlab/catkin_ws/src/seed_r7_ros_pkg/seed_r7_description/meshes/typeF_upperbody/RARM_LINK4_mesh.dae</uri>
            </mesh>
          </geometry>
          <material>
            <script>
              <uri>__default__</uri>
              <name>__default__</name>
            </script>
          </material>
        </visual>
        <gravity>1</gravity>
        <velocity_decay/>
        <self_collide>0</self_collide>
        <enable_wind>0</enable_wind>
        <kinematic>0</kinematic>
      </link>
      <joint name='r_elbow_joint' type='revolute'>
        <child>r_elbow_link</child>
        <parent>r_upperarm_link</parent>
        <axis>
          <xyz>0 1 0</xyz>
          <limit>
            <lower>-3</lower>
            <upper>0</upper>
            <effort>100</effort>
            <velocity>1.2</velocity>
          </limit>
          <dynamics>
            <damping>0.2</damping>
            <friction>0</friction>
            <spring_reference>0</spring_reference>
            <spring_stiffness>0</spring_stiffness>
          </dynamics>
          <use_parent_model_frame>1</use_parent_model_frame>
        </axis>
        <physics>
          <ode>
            <implicit_spring_damper>0</implicit_spring_damper>
            <cfm_damping>0</cfm_damping>
            <limit>
              <cfm>0</cfm>
              <erp>0.2</erp>
            </limit>
          </ode>
        </physics>
      </joint>
      <link name='r_forearm_link'>
        <pose frame=''>-0.01815 -0.183978 1.03895 0 -0 0</pose>
        <inertial>
          <pose frame=''>0.006 0 -0.0738 0 -0 0</pose>
          <mass>0.132</mass>
          <inertia>
            <ixx>0.0007</ixx>
            <ixy>0</ixy>
            <ixz>0</ixz>
            <iyy>0.0007</iyy>
            <iyz>0</iyz>
            <izz>0.0004</izz>
          </inertia>
        </inertial>
        <collision name='r_forearm_link_collision'>
          <pose frame=''>0 0 0 0 -0 1.5708</pose>
          <geometry>
            <mesh>
              <scale>1 1 1</scale>
              <uri>/home/rsdlab/catkin_ws/src/seed_r7_ros_pkg/seed_r7_description/meshes/typeF_upperbody/RARM_LINK5_mesh.dae</uri>
            </mesh>
          </geometry>
          <surface>
            <contact>
              <ode/>
            </contact>
            <friction>
              <ode>
                <mu>0.9</mu>
                <mu2>0.9</mu2>
              </ode>
              <torsional>
                <ode/>
              </torsional>
            </friction>
            <bounce/>
          </surface>
          <max_contacts>10</max_contacts>
        </collision>
        <visual name='r_forearm_link_visual'>
          <pose frame=''>0 0 0 0 -0 1.5708</pose>
          <geometry>
            <mesh>
              <scale>1 1 1</scale>
              <uri>/home/rsdlab/catkin_ws/src/seed_r7_ros_pkg/seed_r7_description/meshes/typeF_upperbody/RARM_LINK5_mesh.dae</uri>
            </mesh>
          </geometry>
          <material>
            <script>
              <uri>__default__</uri>
              <name>__default__</name>
            </script>
          </material>
        </visual>
        <gravity>1</gravity>
        <velocity_decay/>
        <self_collide>0</self_collide>
        <enable_wind>0</enable_wind>
        <kinematic>0</kinematic>
      </link>
      <joint name='r_wrist_y_joint' type='revolute'>
        <child>r_forearm_link</child>
        <parent>r_elbow_link</parent>
        <axis>
          <xyz>0 0 1</xyz>
          <limit>
            <lower>-1.5707</lower>
            <upper>1.5707</upper>
            <effort>100</effort>
            <velocity>1.3</velocity>
          </limit>
          <dynamics>
            <damping>0.2</damping>
            <friction>0</friction>
            <spring_reference>0</spring_reference>
            <spring_stiffness>0</spring_stiffness>
          </dynamics>
          <use_parent_model_frame>1</use_parent_model_frame>
        </axis>
        <physics>
          <ode>
            <implicit_spring_damper>0</implicit_spring_damper>
            <cfm_damping>0</cfm_damping>
            <limit>
              <cfm>0</cfm>
              <erp>0.2</erp>
            </limit>
          </ode>
        </physics>
      </joint>
      <link name='r_wrist_center'>
        <pose frame=''>-0.01815 -0.183978 0.843446 0 -0 0</pose>
        <inertial>
          <pose frame=''>0 0 0 0 -0 0</pose>
          <mass>0.05</mass>
          <inertia>
            <ixx>0.0001</ixx>
            <ixy>0</ixy>
            <ixz>0</ixz>
            <iyy>0.0001</iyy>
            <iyz>0</iyz>
            <izz>0.0001</izz>
          </inertia>
        </inertial>
        <gravity>1</gravity>
        <velocity_decay/>
        <self_collide>0</self_collide>
        <enable_wind>0</enable_wind>
        <kinematic>0</kinematic>
      </link>
      <joint name='r_wrist_p_joint' type='revolute'>
        <child>r_wrist_center</child>
        <parent>r_forearm_link</parent>
        <axis>
          <xyz>0 1 0</xyz>
          <limit>
            <lower>-0.087</lower>
            <upper>0.087</upper>
            <effort>100</effort>
            <velocity>0.9</velocity>
          </limit>
          <dynamics>
            <damping>0.2</damping>
            <friction>0</friction>
            <spring_reference>0</spring_reference>
            <spring_stiffness>0</spring_stiffness>
          </dynamics>
          <use_parent_model_frame>1</use_parent_model_frame>
        </axis>
        <physics>
          <ode>
            <implicit_spring_damper>0</implicit_spring_damper>
            <cfm_damping>0</cfm_damping>
            <limit>
              <cfm>0</cfm>
              <erp>0.2</erp>
            </limit>
          </ode>
        </physics>
      </joint>
      <link name='r_hand_link'>
        <pose frame=''>-0.01815 -0.183978 0.843446 0 -0 0</pose>
        <inertial>
          <pose frame=''>0 0 -0.0875 0 -0 0</pose>
          <mass>0.183</mass>
          <inertia>
            <ixx>0.000601</ixx>
            <ixy>0</ixy>
            <ixz>0</ixz>
            <iyy>0.00055</iyy>
            <iyz>0</iyz>
            <izz>0.000102</izz>
          </inertia>
        </inertial>
        <collision name='r_hand_link_collision'>
          <pose frame=''>0 0 -0.093 0.7 -0 0</pose>
          <geometry>
            <box>
              <size>0.036 0.07 0.03</size>
            </box>
          </geometry>
          <surface>
            <contact>
              <ode/>
            </contact>
            <friction>
              <ode>
                <mu>0.9</mu>
                <mu2>0.9</mu2>
              </ode>
              <torsional>
                <ode/>
              </torsional>
            </friction>
            <bounce/>
          </surface>
          <max_contacts>10</max_contacts>
        </collision>
        <collision name='r_hand_link_collision_1'>
          <pose frame=''>0 -0.007 -0.055 -0.1 0 0</pose>
          <geometry>
            <box>
              <size>0.036 0.05 0.07</size>
            </box>
          </geometry>
          <surface>
            <contact>
              <ode/>
            </contact>
            <friction>
              <ode>
                <mu>0.9</mu>
                <mu2>0.9</mu2>
              </ode>
              <torsional>
                <ode/>
              </torsional>
            </friction>
            <bounce/>
          </surface>
          <max_contacts>10</max_contacts>
        </collision>
        <visual name='r_hand_link_visual'>
          <pose frame=''>0 0 0 0 -0 0</pose>
          <geometry>
            <mesh>
              <scale>1 1 1</scale>
              <uri>/home/rsdlab/catkin_ws/src/seed_r7_ros_pkg/seed_r7_description/meshes/trx_s/RARM_LINK7_mesh.dae</uri>
            </mesh>
          </geometry>
          <material>
            <script>
              <uri>__default__</uri>
              <name>__default__</name>
            </script>
          </material>
        </visual>
        <gravity>1</gravity>
        <velocity_decay/>
        <self_collide>0</self_collide>
        <enable_wind>0</enable_wind>
        <kinematic>0</kinematic>
      </link>
      <joint name='r_wrist_r_joint' type='revolute'>
        <child>r_hand_link</child>
        <parent>r_wrist_center</parent>
        <axis>
          <xyz>1 0 0</xyz>
          <limit>
            <lower>-0.436</lower>
            <upper>1.484</upper>
            <effort>100</effort>
            <velocity>2.1</velocity>
          </limit>
          <dynamics>
            <damping>0.2</damping>
            <friction>0</friction>
            <spring_reference>0</spring_reference>
            <spring_stiffness>0</spring_stiffness>
          </dynamics>
          <use_parent_model_frame>1</use_parent_model_frame>
        </axis>
        <physics>
          <ode>
            <implicit_spring_damper>0</implicit_spring_damper>
            <cfm_damping>0</cfm_damping>
            <limit>
              <cfm>0</cfm>
              <erp>0.2</erp>
            </limit>
          </ode>
        </physics>
      </joint>
      <link name='r_indexbase_link'>
        <pose frame=''>-0.01815 -0.196978 0.728446 0 -0 0</pose>
        <inertial>
          <pose frame=''>0 0.042408 -0.037196 0 -0 0</pose>
          <mass>0.3</mass>
          <inertia>
            <ixx>0.00230024</ixx>
            <ixy>0</ixy>
            <ixz>0</ixz>
            <iyy>0.00034078</iyy>
            <iyz>7.64367e-05</iyz>
            <izz>0.000459461</izz>
          </inertia>
        </inertial>
        <collision name='r_indexbase_link_collision'>
          <pose frame=''>0 0.013494 -0.021422 -0.85 0 0</pose>
          <geometry>
            <box>
              <size>0.041 0.061 0.016</size>
            </box>
          </geometry>
          <surface>
            <contact>
              <ode/>
            </contact>
            <friction>
              <ode>
                <mu>0.9</mu>
                <mu2>0.9</mu2>
              </ode>
              <torsional>
                <ode/>
              </torsional>
            </friction>
            <bounce/>
          </surface>
          <max_contacts>10</max_contacts>
        </collision>
        <collision name='r_indexbase_link_fixed_joint_lump__r_indexmid_link_collision_1'>
          <pose frame=''>0 0.042754 -0.042615 -0.3 0 0</pose>
          <geometry>
            <box>
              <size>0.034 0.03 0.016</size>
            </box>
          </geometry>
          <surface>
            <contact>
              <ode/>
            </contact>
            <friction>
              <ode>
                <mu>0.9</mu>
                <mu2>0.9</mu2>
              </ode>
              <torsional>
                <ode/>
              </torsional>
            </friction>
            <bounce/>
          </surface>
          <max_contacts>10</max_contacts>
        </collision>
        <collision name='r_indexbase_link_fixed_joint_lump__r_indexend_link_collision_2'>
          <pose frame=''>0 0.06347 -0.043972 0 -0 0</pose>
          <geometry>
            <box>
              <size>0.04 0.028 0.016</size>
            </box>
          </geometry>
          <surface>
            <contact>
              <ode/>
            </contact>
            <friction>
              <ode>
                <mu>0.9</mu>
                <mu2>0.9</mu2>
              </ode>
              <torsional>
                <ode/>
              </torsional>
            </friction>
            <bounce/>
          </surface>
          <max_contacts>10</max_contacts>
        </collision>
        <visual name='r_indexbase_link_visual'>
          <pose frame=''>0 0.013 0.115 0 -0 0</pose>
          <geometry>
            <mesh>
              <scale>1 1 1</scale>
              <uri>/home/rsdlab/catkin_ws/src/seed_r7_ros_pkg/seed_r7_description/meshes/trx_s/RARM_INDEX_LINK1_mesh.dae</uri>
            </mesh>
          </geometry>
          <material>
            <script>
              <uri>__default__</uri>
              <name>__default__</name>
            </script>
          </material>
        </visual>
        <visual name='r_indexbase_link_fixed_joint_lump__r_indexmid_link_visual_1'>
          <pose frame=''>0 0.013 0.115 0 -0 0</pose>
          <geometry>
            <mesh>
              <scale>1 1 1</scale>
              <uri>/home/rsdlab/catkin_ws/src/seed_r7_ros_pkg/seed_r7_description/meshes/trx_s/RARM_INDEX_LINK2_mesh.dae</uri>
            </mesh>
          </geometry>
          <material>
            <script>
              <uri>__default__</uri>
              <name>__default__</name>
            </script>
          </material>
        </visual>
        <visual name='r_indexbase_link_fixed_joint_lump__r_indexend_link_visual_2'>
          <pose frame=''>0 0.013 0.115 0 -0 0</pose>
          <geometry>
            <mesh>
              <scale>1 1 1</scale>
              <uri>/home/rsdlab/catkin_ws/src/seed_r7_ros_pkg/seed_r7_description/meshes/trx_s/RARM_INDEX_LINK3_mesh.dae</uri>
            </mesh>
          </geometry>
          <material>
            <script>
              <uri>__default__</uri>
              <name>__default__</name>
            </script>
          </material>
        </visual>
        <velocity_decay/>
        <velocity_decay/>
        <gravity>1</gravity>
        <velocity_decay/>
        <self_collide>0</self_collide>
        <enable_wind>0</enable_wind>
        <kinematic>0</kinematic>
      </link>
      <joint name='r_indexbase_joint' type='revolute'>
        <child>r_indexbase_link</child>
        <parent>r_hand_link</parent>
        <axis>
          <xyz>1 0 0</xyz>
          <limit>
            <lower>-1e+16</lower>
            <upper>1e+16</upper>
          </limit>
          <dynamics>
            <spring_reference>0</spring_reference>
            <spring_stiffness>0</spring_stiffness>
          </dynamics>
          <use_parent_model_frame>1</use_parent_model_frame>
        </axis>
      </joint>
      <link name='r_thumb_link'>
        <pose frame=''>-0.01815 -0.161623 0.763801 0 -0 0</pose>
        <inertial>
          <pose frame=''>0 0.05 -0.06 0 -0 0</pose>
          <mass>0.1</mass>
          <inertia>
            <ixx>0.001</ixx>
            <ixy>0</ixy>
            <ixz>0</ixz>
            <iyy>0.0001</iyy>
            <iyz>0</iyz>
            <izz>0.0001</izz>
          </inertia>
        </inertial>
        <collision name='r_thumb_link_collision'>
          <pose frame=''>0 0.019645 -0.010355 0.63 -0 0</pose>
          <geometry>
            <box>
              <size>0.012 0.008 0.05</size>
            </box>
          </geometry>
          <surface>
            <contact>
              <ode/>
            </contact>
            <friction>
              <ode>
                <mu>0.9</mu>
                <mu2>0.9</mu2>
              </ode>
              <torsional>
                <ode/>
              </torsional>
            </friction>
            <bounce/>
          </surface>
          <max_contacts>10</max_contacts>
        </collision>
        <collision name='r_thumb_link_collision_1'>
          <pose frame=''>0 0.035645 -0.050355 0.1 -0 0</pose>
          <geometry>
            <box>
              <size>0.012 0.008 0.05</size>
            </box>
          </geometry>
          <surface>
            <contact>
              <ode/>
            </contact>
            <friction>
              <ode>
                <mu>0.9</mu>
                <mu2>0.9</mu2>
              </ode>
              <torsional>
                <ode/>
              </torsional>
            </friction>
            <bounce/>
          </surface>
          <max_contacts>10</max_contacts>
        </collision>
        <visual name='r_thumb_link_visual'>
          <pose frame=''>0 -0.022355 0.079645 0 -0 0</pose>
          <geometry>
            <mesh>
              <scale>1 1 1</scale>
              <uri>/home/rsdlab/catkin_ws/src/seed_r7_ros_pkg/seed_r7_description/meshes/trx_s/RARM_THUMB_LINK_mesh.dae</uri>
            </mesh>
          </geometry>
          <material>
            <script>
              <uri>__default__</uri>
              <name>__default__</name>
            </script>
          </material>
        </visual>
        <gravity>1</gravity>
        <velocity_decay/>
        <self_collide>0</self_collide>
        <enable_wind>0</enable_wind>
        <kinematic>0</kinematic>
      </link>
      <joint name='r_thumb_joint' type='revolute'>
        <child>r_thumb_link</child>
        <parent>r_hand_link</parent>
        <axis>
          <xyz>1 0 0</xyz>
          <limit>
            <lower>-1</lower>
            <upper>1</upper>
            <effort>50</effort>
            <velocity>0.5</velocity>
          </limit>
          <dynamics>
            <damping>0.2</damping>
            <friction>0</friction>
            <spring_reference>0</spring_reference>
            <spring_stiffness>0</spring_stiffness>
          </dynamics>
          <use_parent_model_frame>1</use_parent_model_frame>
        </axis>
        <physics>
          <ode>
            <implicit_spring_damper>0</implicit_spring_damper>
            <cfm_damping>0</cfm_damping>
            <limit>
              <cfm>0</cfm>
              <erp>0.2</erp>
            </limit>
          </ode>
        </physics>
      </joint>
      <link name='leg_thigh_link_dummy'>
        <pose frame=''>0.03182 0 0.58318 0 -0 0</pose>
        <inertial>
          <pose frame=''>-0.04 0 0.14 0 -0 0</pose>
          <mass>0.4</mass>
          <inertia>
            <ixx>0.001</ixx>
            <ixy>0</ixy>
            <ixz>0</ixz>
            <iyy>0.001</iyy>
            <iyz>0</iyz>
            <izz>0.001</izz>
          </inertia>
        </inertial>
        <visual name='leg_thigh_link_dummy_visual'>
          <pose frame=''>0 0 0.25 0 -0 0</pose>
          <geometry>
            <mesh>
              <scale>1 1 1</scale>
              <uri>/home/rsdlab/catkin_ws/src/seed_r7_ros_pkg/seed_r7_description/meshes/typeC_lifter/lifter_bone_dummy.dae</uri>
            </mesh>
          </geometry>
        </visual>
        <self_collide>0</self_collide>
        <enable_wind>0</enable_wind>
        <kinematic>0</kinematic>
      </link>
      <joint name='knee_joint_dummy' type='revolute'>
        <child>leg_thigh_link_dummy</child>
        <parent>leg_knee_link</parent>
        <axis>
          <xyz>0 1 0</xyz>
          <limit>
            <lower>-1e+16</lower>
            <upper>1e+16</upper>
          </limit>
          <dynamics>
            <spring_reference>0</spring_reference>
            <spring_stiffness>0</spring_stiffness>
          </dynamics>
          <use_parent_model_frame>1</use_parent_model_frame>
        </axis>
      </joint>
      <link name='leg_shank_link_dummy'>
        <pose frame=''>0.03182 0 0.27682 0 -0 0</pose>
        <inertial>
          <pose frame=''>-0.04 0 0.14 0 -0 0</pose>
          <mass>0.4</mass>
          <inertia>
            <ixx>0.001</ixx>
            <ixy>0</ixy>
            <ixz>0</ixz>
            <iyy>0.001</iyy>
            <iyz>0</iyz>
            <izz>0.001</izz>
          </inertia>
        </inertial>
        <visual name='leg_shank_link_dummy_visual'>
          <pose frame=''>0 0 0.25 0 -0 0</pose>
          <geometry>
            <mesh>
              <scale>1 1 1</scale>
              <uri>/home/rsdlab/catkin_ws/src/seed_r7_ros_pkg/seed_r7_description/meshes/typeC_lifter/lifter_bone_dummy.dae</uri>
            </mesh>
          </geometry>
        </visual>
        <self_collide>0</self_collide>
        <enable_wind>0</enable_wind>
        <kinematic>0</kinematic>
      </link>
      <joint name='ankle_joint_dummy' type='revolute'>
        <child>leg_shank_link_dummy</child>
        <parent>base_link</parent>
        <axis>
          <xyz>0 -1 0</xyz>
          <limit>
            <lower>-1e+16</lower>
            <upper>1e+16</upper>
          </limit>
          <dynamics>
            <spring_reference>0</spring_reference>
            <spring_stiffness>0</spring_stiffness>
          </dynamics>
          <use_parent_model_frame>1</use_parent_model_frame>
        </axis>
      </joint>
      <plugin name='gazebo_ros_control' filename='libgazebo_ros_control.so'>
        <robotNamespace>/</robotNamespace>
        <robotSimType>gazebo_ros_control/DefaultRobotHWSim</robotSimType>
        <legacyModeNS>1</legacyModeNS>
      </plugin>
      <plugin name='cmd_vel_controller' filename='libgazebo_ros_planar_force_move.so'>
        <commandTopic>cmd_vel</commandTopic>
        <odometryTopic>odom</odometryTopic>
        <odometryFrame>odom</odometryFrame>
        <odometryRate>40.0</odometryRate>
        <robotBaseFrame>base_link</robotBaseFrame>
        <useForceFeedback>1</useForceFeedback>
        <appliedForceLink>base_link</appliedForceLink>
        <forceGainX>24000</forceGainX>
        <forceGainY>24000</forceGainY>
        <forceGainRot>6000</forceGainRot>
        <robotNamespace>/</robotNamespace>
      </plugin>
      <static>0</static>
      <plugin name='mimic_updater' filename='libmimic_plugin.so'>
        <mimic D='10' I='0.1' P='100' command_max='200' command_min='-200' i_max='0' i_min='0' joint='knee_joint' multiplier='-1.0' offset='0.0' velocity='1'>knee_joint_mimic</mimic>
        <mimic D='10' I='0.1' P='100' command_max='200' command_min='-200' i_max='0' i_min='0' joint='ankle_joint' multiplier='-1.0' offset='0.0' velocity='1'>ankle_joint_mimic</mimic>
        <mimic D='10' I='0.0' P='100' command_max='200' command_min='-200' i_max='0' i_min='0' joint='knee_joint' multiplier='-1.0' offset='0.0' velocity='1'>knee_joint_dummy</mimic>
        <mimic D='10' I='0.0' P='100' command_max='200' command_min='-200' i_max='0' i_min='0' joint='ankle_joint' multiplier='1.0' offset='0.0' velocity='1'>ankle_joint_dummy</mimic>
        <mimic D='1' I='0.0' P='10' command_max='50' command_min='-50' i_max='0' i_min='0' joint='l_thumb_joint' multiplier='-1.0' offset='0.0' velocity='1'>l_indexbase_joint</mimic>
        <mimic D='1' I='0.0' P='10' command_max='50' command_min='-50' i_max='0' i_min='0' joint='r_thumb_joint' multiplier='-1.0' offset='0.0' velocity='1'>r_indexbase_joint</mimic>
        <robotNamespace>/</robotNamespace>
      </plugin>
      <pose frame=''>0.038 0.016 0 0 -0 0</pose>
    </model>
  </world>
</sdf>
